Workbook

Sheet 様式２－１
A1: 様式１－１
AA2: 宮ア連 | AF2: 発第 | AH2: 800 | AN2: 号
AA3: 令和 | AC3: 8 | AF3: 年 | AG3: 3 | AJ3: 月 | AK3: 9 | AN3: 日
A5: 公益財団法人 宮崎県スポーツ協会
A6: 理事長 黒 木 淳 一 郎 様
W9: 団 体 名 | AB9: アイスホッケー | AI9: 連盟
W11: 代表者職・氏名 | AB11: 黒木誠一郎 | AL11: 公印
B15: 令和 | E15: 7 | G15: 年度 | J15: 宮崎国スポ強化戦略プロジェクト補助金事業報告
A18: 令和 ７年１２月２３日付け宮スポ協第３３５号で交付決定通知のありました標記補助金につい
A19: について下記のとおり報告いたします。
T22: 記
A24: １ 添付書類
A25: 〇 収支決算書 | N25: (様式２－２) | T25: ※すべてのプロジェクトの決算をまとめたもの
A26: ○ 事業別決算書 | N26: (様式２－２－１) | V26: ※各種プロジェクト様式
A27: 〇 変更実績報告書 | N27: (様式２－３) ※補助金内変更の場合のみ提出
A28: ○ 事業実施・実績報告書 | N28: (様式２－４) | V28: ※各種プロジェクト様式
A29: ○ 事業別参加者名簿 | N29: (様式２－５)
A30: ○ 事業別領収書(原本) | N30: (様式２－６，２－７)
A31: ○ 事業別スナップ写真 | N31: (様式２－８)
A33: ２ 競技団体保管書類
A34: ○ 領収書(コピー) | L34: (様式２－６、２－７)
A38: ３ 記入上の注意
A39: ○ 令和 年 月 日付け宮スポ協第 号の欄は、交付決定通知日付け並びにその
A40: 文書番号を記入のこと。
A41: ○ 印鑑については、会長公印を押印する。
W42: 担当者 | AA42: 齋藤 豊光
W43: ＴＥＬ | AA43: ０９０－８２２４－０８４２
W44: ＦＡＸ | AA44: ０９８５－７３－２７６８
W45: E-mail | AA45: toyo2768@gmail.com

Sheet 様式２－２
A1: 様式２－２
C3: 令和 | F3: ='様式２－１'!E15 -> 7 | H3: 年度 | M3: 宮崎国スポ強化戦略プロジェクト 収支決算書
A5: １ 収 入 | AE5: 単位：円
B6: 費 目 | J6: 金 額 | Q6: 内 訳
B7: １ 補助金 | J7: 2625000 | Q7: 宮崎県スポーツ協会からの補助金（①＋②＋③）
B8: ２ 負担金 | J8: 15309 | Q8: 競技団体負担金
B9: ３ その他
B10: 収入合計 | J10: =SUM(J7:P9) -> 2640309
A12: ２ 支 出 | AE12: 単位：円
B13: 費 目 | J13: 金 額 | Q13: 内 訳
Q14: ①国スポ選手 強化プロジェクト (選手強化費） | X14: ②トップチーム 活用事業 | AE14: ③ふるさと選手活動 支援プロジェクト
B15: １ 対象経費 | J15: =J16+J23+J25+J27+J29+J31 -> 2640309 | Q15: =Q16+Q23+Q25+Q27+Q29+Q31 -> 1886850 | X15: =X16+X23+X25+X27+X29 -> 0 | AN15: 交通費 | AO15: 宿泊費 | AP15: 雑費 | AQ15: 合計
C16: (1) 旅費 | J16: =SUM(J17:P22) -> 1779859 | Q16: =SUM(Q17:W22) -> 1026400 | X16: =SUM(X17:AD22) -> 0 | AE16: =SUM(AE17:AK22) -> 753459 | AM16: ① | AN16: 14110 | AP16: 15400 | AQ16: =SUM(AN16:AP16) -> 29510
D17: ① 交通費 | J17: =SUM(Q17:AK18) -> 1366669 | Q17: ='様式２－２－１ 事業別決算書（選手強化費）'!J16 -> 830550 | X17: ='様式２－２－１ 事業別決算書（トップチーム活用)'!J16 -> 0 | AE17: ='様式２－２－１ 事業別決算書（ふるさと）'!J16 -> 536119 | AM17: ② | AN17: 14110 | AP17: 15400 | AQ17: =SUM(AN17:AP17) -> 29510
AM18: ③ | AN18: 10455 | AP18: 15400 | AQ18: =SUM(AN18:AP18) -> 25855
D19: ② 宿泊費 | J19: =SUM(Q19:AK20) -> 104990 | Q19: ='様式２－２－１ 事業別決算書（選手強化費）'!J18 -> 81250 | X19: ='様式２－２－１ 事業別決算書（トップチーム活用)'!J18 -> 0 | AE19: ='様式２－２－１ 事業別決算書（ふるさと）'!J18 -> 23740 | AM19: ④ | AN19: 10895 | AP19: 15400 | AQ19: =SUM(AN19:AP19) -> 26295
AM20: ➄ | AN20: 93770 | AP20: 17600 | AQ20: =SUM(AN20:AP20) -> 111370
D21: ③ 旅行雑費 | J21: =SUM(Q21:AK22) -> 308200 | Q21: ='様式２－２－１ 事業別決算書（選手強化費）'!J20 -> 114600 | AE21: ='様式２－２－１ 事業別決算書（ふるさと）'!J20 -> 193600 | AM21: ⑥ | AN21: 8415 | AP21: 15400 | AQ21: =SUM(AN21:AP21) -> 23815
AM22: ⑦ | AN22: 144905 | AO22: 12500 | AP22: 22000 | AQ22: =SUM(AN22:AP22) -> 179405
C23: (2) 使用料賃借料 | J23: =SUM(Q23:AK24) -> 373450 | Q23: ='様式２－２－１ 事業別決算書（選手強化費）'!$J$24 -> 373450 | X23: ='様式２－２－１ 事業別決算書（トップチーム活用)'!J22 -> 0 | AM23: ⑧ | AN23: 69370 | AO23: 11240 | AP23: 19800 | AQ23: =SUM(AN23:AP23) -> 100410
AM24: ⑨ | AN24: 10895 | AP24: 15400 | AQ24: =SUM(AN24:AP24) -> 26295
C25: (3) 報償費 | J25: =SUM(Q25:AK26) -> 0 | Q25: ='様式２－２－１ 事業別決算書（選手強化費）'!$J$26 -> 0 | X25: ='様式２－２－１ 事業別決算書（トップチーム活用)'!J24 -> 0 | AM25: ⑩ | AQ25: =SUM(AN25:AP25) -> 0
AM26: ⑪ | AQ26: =SUM(AN26:AP26) -> 0
C27: (4) 需用費 | J27: =SUM(Q27:AK27) -> 487000 | Q27: ='様式２－２－１ 事業別決算書（選手強化費）'!$J$28 -> 487000 | X27: ='様式２－２－１ 事業別決算書（トップチーム活用)'!$J$28 -> 0 | AE27: ='様式２－２－１ 事業別決算書（ふるさと）'!J28 -> 0 | AM27: ⑫ | AQ27: =SUM(AN27:AP27) -> 0
AM28: ⑬ | AN28: 61628 | AP28: 17600 | AQ28: =SUM(AN28:AP28) -> 79228
C29: (5) 役務費 | J29: =SUM(Q29:AK30) -> 0 | Q29: ='様式２－２－１ 事業別決算書（選手強化費）'!$J$30 -> 0 | X29: ='様式２－２－１ 事業別決算書（トップチーム活用)'!$J$30 -> 0 | AE29: ='様式２－２－１ 事業別決算書（ふるさと）'!J30 -> 0 | AM29: ⑭ | AQ29: =SUM(AN29:AP29) -> 0
AM30: ⑮ | AN30: 7480 | AP30: 4400 | AQ30: =SUM(AN30:AP30) -> 11880
C31: (6) 駐車料金 | J31: =SUM(Q31:AK32) -> 0 | Q31: ='様式２－２－１ 事業別決算書（選手強化費）'!$J$22 -> 0 | AM31: ⑯ | AN31: 7480 | AP31: 4400 | AQ31: =SUM(AN31:AP31) -> 11880
AM32: ⑰ | AN32: 82606 | AP32: 15400 | AQ32: =SUM(AN32:AP32) -> 98006
B33: ２ 対象外経費 | J33: =SUM(Q33:AK34) -> 0 | Q33: ='様式２－２－１ 事業別決算書（選手強化費）'!$J$32 -> 0 | X33: ='様式２－２－１ 事業別決算書（トップチーム活用)'!$J$32 -> 0 | AE33: ='様式２－２－１ 事業別決算書（ふるさと）'!J32 -> 0
B35: 支出合計 | J35: =(J33)+(J15) -> 2640309 | AM35: 計 | AN35: =SUM(AN16:AN32) -> 536119 | AO35: =SUM(AO22:AO34) -> 23740 | AP35: =SUM(AP16:AP32) -> 193600 | AQ35: =SUM(AQ16:AQ33) -> 753459 | AR35: =SUM(AN35:AP35) -> 753459
Q36: ※ 各事業の収支決算書の数字がリンクします
A37: 【記入上の注意】
B38: １ 網掛け部分は対象外。金額欄は桁区切が入っているため、そのまま数値を入れること。
B39: ２ 補助金については、内示額を入力すること。
B40: ３ 県内外15,000円を超える宿泊費（消費税込）等、本会が定めた宿泊料金を超過する部分 は、補助対象外とする。
B41: ４ 旅行パック使用時の旅費については、対象経費の宿泊費を除いた金額を交通費にする。
B42: ※ 他の事業（国スポ派遣費、個人指定、女性アスリート、大学・社会人等）と領収書の重複がないようご注意ください。 ※ ポイント還元やキャンペーン等との併用はできませんのでご注意ください。

Sheet 様式２－２－１　事業別決算書（選手強化費）
A1: 様式２－２－１事業別決算書
E2: 令和 | H2: 7 | J2: 年度 | N2: ①国スポ選手強化プロジェクト・選手強化費補助金 収支決算書
A4: １ 収入 | AI4: 単位：円
B6: 科 目 | J6: 決算額 | O6: 内 訳
B7: １ 補 助 金 | J7: 1871541 | O7: 宮崎県スポーツ協会からの補助金 ①
B8: ２ 負 担 金 | J8: 15309 | O8: 競技団体負担金
B9: ３ そ の 他
B10: 合 計 | J10: =J7+J8+J9 -> 1886850
A12: ２ 支出 | AI12: 単位：円
B13: 科 目 | J13: 決算額 | O13: 内 訳
B14: １ 対 象 経 費 | J14: =J15+J22+J24+J30+J26+J28 -> 1886850 | O14: ②
C15: （１）旅 費 | J15: =SUM(J16:N21) -> 1026400
D16: ① 交 通 費 | J16: 830550 | O16: 成年男子 | S16: 830550 | Y16: 円 | AB16: 成年女子 | AL16: 円
O17: 少年男子 | Y17: 円 | AB17: 少年女子 | AL17: 円
D18: ② 宿 泊 費 | J18: 81250 | O18: 成年男子 | S18: 81250 | Y18: 円 | AB18: 成年女子 | AL18: 円
O19: 少年男子 | Y19: 円 | AB19: 少年女子 | AL19: 円
D20: ③ 旅行雑費 | J20: 114600 | O20: 成年男子 | S20: 114600 | Y20: 円 | AB20: 成年女子 | AL20: 円
O21: 少年男子 | Y21: 円 | AB21: 少年女子 | AL21: 円
C22: （３）駐車料金 | O22: 成年男子 | Y22: 円 | AB22: 成年女子 | AL22: 円
O23: 少年男子 | Y23: 円 | AB23: 少年女子 | AL23: 円
C24: （４）借 用 料 | J24: 373450 | O24: 成年男子 | S24: 373450 | Y24: 円 | AB24: 成年女子 | AL24: 円
C25: ※会場使用料等 | O25: 少年男子 | Y25: 円 | AB25: 少年女子 | AL25: 円
C26: （５）報 償 費 | O26: 成年男子 | Y26: 円 | AB26: 成年女子 | AL26: 円
C27: ※競技団体所属外の指導者 | O27: 少年男子 | Y27: 円 | AB27: 少年女子 | AL27: 円
C28: （６）需 用 費 | J28: 487000 | O28: 成年男子 | S28: 487000 | Y28: 円 | AB28: 成年女子 | AL28: 円
C29: ※競技用消耗品等 | O29: 少年男子 | Y29: 円 | AB29: 少年女子 | AL29: 円
C30: （７）役 務 費 | O30: 成年男子 | Y30: 円 | AB30: 成年女子 | AL30: 円
C31: 振込手数料のみ | O31: 少年男子 | Y31: 円 | AB31: 少年女子 | AL31: 円
B32: ２ 対 象 外 経 費 | O32: 成年男子 | Y32: 円 | AB32: 成年女子 | AL32: 円
O33: 少年男子 | Y33: 円 | AB33: 少年女子 | AL33: 円
B34: 支 出 合 計 | J34: =(J32)+(J14) -> 1399850
A35: ３ 差引額
D36: 補助金① | J36: =J7 -> 1871541 | O36: － | P36: 対象経費② | T36: =J14 -> 1886850 | Y36: ＝ | Z36: 差引額 | AC36: =J36-T36 -> -15309
B37: ※差引額がマイナスの場合は、戻入不要。
B39: ※ 記入上の注意
B40: １ 補助金については、内示額であり，種別毎に内示したものの合計額になる。
B41: ２ 対象外経費 県内外15,000円を超える宿泊費（消費税込）、弁当代等
B42: 本会が定めた宿泊料金を超過する部分は、補助対象外とする。
B43: ３ 旅行パック使用時の旅費記入については、対象経費の宿泊費額を除いた金額を交通費にする。
B44: ※ 他の事業（国スポ派遣費、個人指定、女性アスリート、大学・社会人等）と領収書の重複がないようご注意ください。 ※ ポイント還元やキャンペーン等との併用はできませんのでご注意ください。

Sheet 様式２－２－１　事業別決算書（トップチーム活用)
A1: 様式２－２－１事業別決算書
E3: 令和 | H3: 7 | J3: 年度 | N3: ②トップチーム活用事業補助金 収支決算書
A5: １ 収 入 | AI5: 単位：円
B6: 費 目 | J6: 金 額 | O6: 内 訳
B7: １ 補助金 | J7: 0 | O7: 宮崎県スポーツ協会からの補助金
B8: ２ 負担金 | J8: 0 | O8: 競技団体負担金
B9: ３ その他 | J9: 0
B10: 収入合計 | J10: =SUM(J7:N9) -> 0
A12: ２ 支 出 | AI12: 単位：円
B13: 費 目 | J13: 金 額 | O13: 内 訳
B14: １ 対象経費 | J14: =J15+J28+J30+J22+J24 -> 0 | O14: (1)＋(5)＋(6)
C15: (1) 旅費 | J15: =SUM(J16:N19) -> 0 | O15: ①＋②＋③
D16: ① 交通費
D18: ② 宿泊費
D20: ③ 旅行雑費
C22: (2) 使用料賃借料
C24: (3) 報償費
C26: (4) 食糧費
C28: (5) 需用費
C30: (6) 役務費
B32: ２ 対象外経費
B34: 支出合計 | J34: =(J32)+(J14) -> 0 | O34: １＋２
A36: ３ 差引額 | H36: 1補助金 | L36: =(J7) -> 0 | Q36: － | S36: １対象経費 | W36: =(J14) -> 0 | AB36: ＝ | AD36: 差引額 | AG36: =(L36)-(W36) -> 0
B37: ※ 差引額がマイナスになる場合は、戻入不要。
A38: 【記入上の注意】
B39: １ 網掛け部分は対象外。金額欄は桁区切が入っているため、そのまま数値を入れること。
B40: ２ 補助金については、内示額を入力すること。
B41: ３ 県内外15,000円を超える宿泊費（消費税込）等、本会が定めた宿泊料金を超過する部分は、 補助対象外とする。
B42: ４ 旅行パック使用時の旅費については、対象経費の宿泊費を除いた金額を交通費にする。
B43: ※ 他の事業（国スポ派遣費、個人指定、女性アスリート、大学・社会人等）と領収書の重複が ないようご注意ください。 ※ ポイント還元やキャンペーン等との併用はできませんのでご注意ください。

Sheet 様式２－２－１　事業別決算書（ふるさと）
A1: 様式２－２－１事業別決算書
E3: 令和 | H3: 7 | J3: 年度 | N3: ③ふるさと選手活動支援プロジェクト補助金 収支決算書
A5: １ 収 入 | AI5: 単位：円
B6: 費 目 | J6: 金 額 | O6: 内 訳
B7: １ 補助金 | J7: 605000 | O7: 宮崎県スポーツ協会からの補助金 ※対象者：男(13) 女(0)
B8: ２ 負担金 | J8: 0 | O8: 競技団体負担金
B9: ３ その他 | J9: 0
B10: 収入合計 | J10: =SUM(J7:N9) -> 605000
A12: ２ 支 出 | AI12: 単位：円
B13: 費 目 | J13: 金 額 | O13: 内 訳
B14: １ 対象経費 | J14: =J15+J28+J30 -> 753459 | O14: (1)＋(5)＋(6)
C15: (1) 旅費 | J15: =SUM(J16:N21) -> 753459 | O15: ①＋②＋③
D16: ① 交通費 | J16: 536119 | O16: 【5/24】14,110円【6/14】14,110円【8/24】10,455円【9/13】10,895円【9/27】93,770円【10/4】8,415円【10/25】144,905円【11/8】69,370円【11/22】10,895円【1/24】61,628円【2/7】7,480円【2/21】7,480円【2/28】82,606円
D18: ② 宿泊費 | J18: 23740 | O18: 6,250円×２回＋5,620円×２回
D20: ③ 旅行雑費 | J20: 193600 | O20: 4,400×2回＋15,400円×7回＋17,600円×2回＋19,800円＋22,000円
C22: (2) 使用料賃借料
C24: (3) 報償費
C26: (4) 食糧費
C28: (5) 需用費
C30: (6) 役務費
B32: ２ 対象外経費
B34: 支出合計 | J34: =(J32)+(J14) -> 753459 | O34: １＋２
A36: ３ 差引額 | H36: 1補助金 | L36: =(J7) -> 605000 | Q36: － | S36: １対象経費 | W36: =(J14) -> 753459 | AB36: ＝ | AD36: 差引額 | AG36: =(L36)-(W36) -> -148459
B37: ※ 差引額がマイナスになる場合は、戻入不要。
A38: 【記入上の注意】
B39: １ 網掛け部分は対象外。金額欄は桁区切が入っているため、そのまま数値を入れること。
B40: ２ 補助金については、内示額を入力すること。
B41: ３ 県内外15,000円を超える宿泊費（消費税込）等、本会が定めた宿泊料金を超過する部分は、 補助対象外とする。
B42: ４ 旅行パック使用時の旅費については、対象経費の宿泊費を除いた金額を交通費にする。
B43: ※ 他の事業（国スポ派遣費、個人指定、女性アスリート、大学・社会人等）と領収書の重複が ないようご注意ください。 ※ ポイント還元やキャンペーン等との併用はできませんのでご注意ください。

Sheet 様式２－３
A1: 様式２－３ | V1: （ アイスホッケー ）競技
C3: 変 更 実 績 報 告 書
M4: ※内示額より変更の場合のみ提出
A5: ①選手強化費内での種別間変更
B6: 種 別 | K6: 内 示 額 | T6: 移 動 額 | AC6: 種 別(移動先)
B13: 例）少年男子 | K13: 1,230,000円 | T13: 230,000円 | AC13: 成年男子
A15: ①選手強化費 ②トップチーム活用事業 ③ふるさと選手活動支援での変更
B16: 補助金名 | K16: 内 示 額 | T16: 移 動 額 | AC16: 補助金名(移動先)
B17: 選手強化 | K17: 2020000 | T17: 145239 | AC17: ふるさと選手 | AM17: 1781400 | AO17: 605000
AM18: 238600 | AO18: 729719
AM19: =SUM(AM17:AM18) -> 2020000 | AO19: =AO18-AO17 -> 124719
B21: 例）①選手強化費 | K21: 1,057,900円 | T21: 300,000円 | AC21: ②トップチーム活用事業
A23: 補助額変更後
B24: ①選手強化費 | K24: 内 示 額 | T24: 移 動 後 の 総 額 | AC24: 総 額（合計）
B25: 成年男子 | K25: 2020000 | L25: =SUM(L23:L24) -> 0 | M25: =SUM(M23:M24) -> 0 | N25: =SUM(N23:N24) -> 0 | O25: =SUM(O23:O24) -> 0 | P25: =SUM(P23:P24) -> 0 | Q25: =SUM(Q23:Q24) -> 0 | R25: =SUM(R23:R24) -> 0 | S25: =SUM(S23:S24) -> 0 | T25: 1874761 | AC25: 1874761
B26: 成年女子
B27: 少年男子
B28: 少年女子
B29: ②トップチーム活用事業 | K29: 内 示 額 | T29: 移 動 後 の 総 額 | AC29: 総 額（合計）
B30: 例）少年男子
B31: 例）少年女子
B32: ③ふるさと選手活動支援 | K32: 内 示 額 | T32: 移 動 後 の 総 額 | AC32: 総 額（合計）合計
B33: 成年男子 | K33: 605000 | T33: 750239 | AC33: 750239
B34: ※種別等の記入は競技団体の実態に合わせて御記入ください。

Sheet 様式２－４①②事業実施・実績報告書（選手強化費）
A1: 様式２－４①②事業実施・実績報告書
A2: 令和 ７年度 国スポ選手強化プロジェクト（①選手強化費）事業実施報告書
A4: （ アイスホッケー ）競技
A7: 事 業 名 | D7: 強化練習 ・ 遠征試合 | U7: 強化練習 ・ 遠征試合
D10: （該当するものを○で囲む） | U10: （該当するものを○で囲む）
A11: 種 別 | D11: 成年男子 ・ 成年女子 少年男子 ・ 少年女子 | U11: 成年男子 ・ 成年女子 少年男子 ・ 少年女子
D14: （該当するものを○で囲む） | U14: （該当するものを○で囲む）
A15: 期 日 | D15: 令和 ７年 ５月２４日（土） | U15: 令和 ７年 ６月１４日（土）
A16: 場所 | B16: 会 場 | D16: 福岡オービジョンアリーナ | U16: 福岡オービジョンアリーナ
B17: 宿舎名 | D17: 宿泊なし | U17: 宿泊なし
A18: 参 加 人 員 | D18: 指導者 | G18: 0 | I18: 名 | K18: 選手 | M18: 3 | O18: 名 | U18: 指導者 | X18: 1 | Z18: 名 | AB18: 選手 | AD18: 3 | AF18: 名
Q19: 計 | R19: 3 | T19: 名 | AH19: 計 | AI19: =IF(OR(X18="",AD18=""),"",SUM(X18,AD18)) -> 4 | AK19: 名
A20: 支 出 の 内 訳 | B20: 科 目 | D20: 金 額 | H20: 内 訳 | U20: 金 額 | Y20: 内 訳
B21: 交 通 費 | D21: 61700 | U21: 76540
B22: 宿 泊 費 | L22: 円 | M22: × | P22: 名 | Q22: × | T22: 泊 | U22: =IF(OR(Z22="",AE22="",AI22=""),"",(Z22*AE22*AI22)) | AC22: 円 | AD22: × | AG22: 名 | AH22: × | AK22: 泊
B23: 旅行雑費 | D23: 6600 | I23: 1100 | L23: 円 | M23: × | N23: 3 | P23: 名 | Q23: × | R23: 2 | T23: 日 | U23: 8800 | Z23: 1100 | AC23: 円 | AD23: × | AE23: 4 | AG23: 名 | AH23: × | AI23: 2 | AK23: 日
B24: 駐 車 料 | U24: =IF(OR(Z24="",AE24="",AI24=""),"",(Z24*AE24*AI24))
B25: 借 用 料 | D25: 15750 | L25: 円 | M25: × | P25: 日 | U25: 26750 | AC25: 円 | AD25: × | AG25: 日
B26: 需 用 費 | U26: =IF(OR(Z26="",AF26=""),"",(Z26*AF26))
B27: 役 務 費
B28: そ の 他
B34: 計 | D34: =SUM(D21:G33) -> 84050 | U34: =SUM(U21:X33) -> 112090
A35: 日程及び内容 | D35: 21:15～ 大分選抜との練習試合 （ １ 対 ９ ） 23:00 終了 | U35: 21:15～ 九州大学との練習試合 （ ２ 対 ４ ） 23:00 終了
A41: 事業の成果 | D41: 技術力・チーム連携の向上 | U41: 技術力・チーム連携の向上
A47: 記入責任者氏名（ 齋藤 和明 ） 電話番号（ 090-5288-9928 ）

Sheet 様式２－４③④事業実施・実績報告（選手強化）
A1: 様式２－４③④事業実施・実績報告書
A2: 令和 ７年度 国スポ選手強化プロジェクト（①選手強化費）事業実施報告書
A4: （ アイスホッケー ）競技
A7: 事 業 名 | D7: 強化練習 ・ 遠征試合 | U7: 強化練習 ・ 遠征試合
D10: （該当するものを○で囲む） | U10: （該当するものを○で囲む）
A11: 種 別 | D11: 成年男子 ・ 成年女子 少年男子 ・ 少年女子 | U11: 成年男子 ・ 成年女子 少年男子 ・ 少年女子
D14: （該当するものを○で囲む） | U14: （該当するものを○で囲む）
A15: 期 日 | D15: 令和 ７年 ８月２３日（土） | U15: 令和 ７年 ９月１３（土）
A16: 場所 | B16: 会 場 | D16: スポガ久留米 | U16: スポガ久留米
B17: 宿舎名 | D17: 宿泊なし | U17: 宿伯なし
A18: 参 加 人 員 | G18: 1 | I18: 名 | K18: 選手 | M18: 3 | O18: 名 | U18: 指導者 | X18: 1 | Z18: 名 | AB18: 選手 | AD18: 3 | AF18: 名
Q19: 計 | R19: =IF(OR(G18="",M18=""),"",SUM(G18,M18)) -> 4 | T19: 名 | AH19: 計 | AI19: =IF(OR(X18="",AD18=""),"",SUM(X18,AD18)) -> 4 | AK19: 名
A20: 支 出 の 内 訳 | B20: 科 目 | D20: 金 額 | H20: 内 訳 | U20: 金 額 | Y20: 内 訳
B21: 交 通 費 | D21: 67630 | U21: 72700
B22: 宿 泊 費 | L22: 円 | M22: × | P22: 名 | Q22: × | T22: 泊 | U22: =IF(OR(Z22="",AE22="",AI22=""),"",(Z22*AE22*AI22)) | AC22: 円 | AD22: × | AG22: 名 | AH22: × | AK22: 泊
B23: 旅行雑費 | D23: 8800 | I23: 1100 | L23: 円 | M23: × | N23: 4 | P23: 名 | Q23: × | R23: 2 | T23: 日 | U23: 8800 | Z23: 1100 | AC23: 円 | AD23: × | AE23: 4 | AG23: 名 | AH23: × | AI23: 2 | AK23: 日
B24: 駐 車 料 | U24: =IF(OR(Z24="",AE24="",AI24=""),"",(Z24*AE24*AI24))
B25: 借 用 料 | D25: 36000 | L25: 円 | M25: × | P25: 日 | U25: 15000 | AC25: 円 | AD25: × | AG25: 日
B26: 需 用 費 | U26: =IF(OR(Z26="",AF26=""),"",(Z26*AF26))
B27: 役 務 費
B28: そ の 他
B34: 計 | D34: =SUM(D21:G33) -> 112430 | U34: =SUM(U21:X33) -> 96500
A35: 日程及び内容 | D35: 22:15～23:45 遠征試合 〇宮崎県選抜 対 鹿児島県選抜 ８ ２ | U35: 22:15～23:45 強化練習 参加：宮崎県選抜、鹿児島県選抜 久留米クラブ
A41: 事業の成果 | D41: 技術力・チーム連携の向上 | U41: 技術力・チーム連携の向上
A47: 記入責任者氏名（ 齋藤 和明 ） 電話番号（ 090-5288-9928 ）

Sheet 様式２－４➄⑥事業実施・実績報告（選手強化）
A1: 様式２－➄⑥事業実施・実績報告書
A2: 令和 ７年度 国スポ選手強化プロジェクト（①選手強化費）事業実施報告書
A4: （ アイスホッケー ）競技
A7: 事 業 名 | D7: 強化練習 ・ 遠征試合 | U7: 強化練習 ・ 遠征試合
D10: （該当するものを○で囲む） | U10: （該当するものを○で囲む）
A11: 種 別 | D11: 成年男子 ・ 成年女子 少年男子 ・ 少年女子 | U11: 成年男子 ・ 成年女子 少年男子 ・ 少年女子
D14: （該当するものを○で囲む） | U14: （該当するものを○で囲む）
A15: 期 日 | D15: 令和 ７年 ９月２７日（土） | U15: 令和 ７年１０月 ４（土）
A16: 場所 | B16: 会 場 | D16: 福岡オービジョンアリーナ | U16: スポガ久留米
B17: 宿舎名 | D17: 宿泊なし | U17: 宿泊なし
A18: 参 加 人 員 | D18: 指導者 | G18: 2 | I18: 名 | K18: 選手 | M18: 2 | O18: 名 | U18: 指導者 | X18: 1 | Z18: 名 | AB18: 選手 | AD18: 1 | AF18: 名
Q19: 計 | R19: =IF(OR(G18="",M18=""),"",SUM(G18,M18)) -> 4 | T19: 名 | AH19: 計 | AI19: =IF(OR(X18="",AD18=""),"",SUM(X18,AD18)) -> 2 | AK19: 名
A20: 支 出 の 内 訳 | B20: 科 目 | D20: 金 額 | H20: 内 訳 | U20: 金 額 | Y20: 内 訳
B21: 交 通 費 | D21: 76880 | U21: 33700
B22: 宿 泊 費 | L22: 円 | M22: × | P22: 名 | Q22: × | T22: 泊 | U22: =IF(OR(Z22="",AE22="",AI22=""),"",(Z22*AE22*AI22)) | AC22: 円 | AD22: × | AG22: 名 | AH22: × | AK22: 泊
B23: 旅行雑費 | D23: 8800 | I23: 1100 | L23: 円 | M23: × | N23: 4 | P23: 名 | Q23: × | R23: 2 | T23: 日 | U23: 4400 | Z23: 1100 | AC23: 円 | AD23: × | AE23: 2 | AG23: 名 | AH23: × | AI23: 2 | AK23: 日
B24: 駐 車 料 | U24: =IF(OR(Z24="",AE24="",AI24=""),"",(Z24*AE24*AI24))
B25: 借 用 料 | D25: 29200 | L25: 円 | M25: × | P25: 日 | U25: 15000 | AC25: 円 | AD25: × | AG25: 日
B26: 需 用 費 | U26: =IF(OR(Z26="",AF26=""),"",(Z26*AF26))
B27: 役 務 費
B28: そ の 他
B34: 計 | D34: =SUM(D21:G33) -> 114880 | U34: =SUM(U21:X33) -> 53100
A35: 日程及び内容 | D35: 23:00～24:30 練習試合 ●宮崎県選抜 対 福岡ブルーインズ ７ ８ | U35: 22:15～23:45 強化練習 参加：宮崎県選抜・鹿児島県選抜 久留米クラブ
A41: 事業の成果 | D41: 技術力・チーム連携の向上 | U41: 技術力・チーム連携の向上
A47: 記入責任者氏名（ 齋藤 和明 ） 電話番号（ 090-5288-9928 ）

Sheet 様式２－４⑦⑧事業実施・実績報告（選手強化）
A1: 様式２－⑦⑧事業実施・実績報告書
A2: 令和 ７年度 国スポ選手強化プロジェクト（①選手強化費）事業実施報告書
A4: （ アイスホッケー ）競技
A7: 事 業 名 | D7: 強化練習 ・ 遠征試合 | U7: 強化練習 ・ 遠征試合
D10: （該当するものを○で囲む） | U10: （該当するものを○で囲む）
A11: 種 別 | D11: 成年男子 ・ 成年女子 少年男子 ・ 少年女子 | U11: 成年男子 ・ 成年女子 少年男子 ・ 少年女子
D14: （該当するものを○で囲む） | U14: （該当するものを○で囲む）
A15: 期 日 | D15: 令和 ７年１０月２５日（土） | U15: 令和 ７年１１月 ８日（土）
A16: 場所 | B16: 会 場 | D16: スポガ久留米 | U16: 福岡オービジョンアリーナ
B17: 宿舎名 | D17: 宿泊なし | U17: 宿泊なし
A18: 参 加 人 員 | D18: 指導者 | G18: 1 | I18: 名 | K18: 選手 | M18: 2 | O18: 名 | U18: 指導者 | X18: 1 | Z18: 名 | AB18: 選手 | AD18: 3 | AF18: 名
Q19: 計 | R19: =IF(OR(G18="",M18=""),"",SUM(G18,M18)) -> 3 | T19: 名 | AH19: 計 | AI19: =IF(OR(X18="",AD18=""),"",SUM(X18,AD18)) -> 4 | AK19: 名
A20: 支 出 の 内 訳 | B20: 科 目 | D20: 金 額 | H20: 内 訳 | U20: 金 額 | Y20: 内 訳
B21: 交 通 費 | D21: 51000 | U21: 67960
B22: 宿 泊 費 | L22: 円 | M22: × | P22: 名 | Q22: × | T22: 泊 | AC22: 円 | AD22: × | AG22: 名 | AH22: × | AK22: 泊
B23: 旅行雑費 | D23: 6600 | I23: 1100 | L23: 円 | M23: × | N23: 3 | P23: 名 | Q23: × | R23: 2 | T23: 日 | U23: 8800 | Z23: 1100 | AC23: 円 | AD23: × | AE23: 4 | AG23: 名 | AH23: × | AI23: 2 | AK23: 日
B24: 駐 車 料 | U24: =IF(OR(Z24="",AE24="",AI24=""),"",(Z24*AE24*AI24))
B25: 借 用 料 | D25: 15000 | L25: 円 | M25: × | P25: 日 | U25: 10000 | AC25: 円 | AD25: × | AG25: 日
B26: 需 用 費 | U26: =IF(OR(Z26="",AF26=""),"",(Z26*AF26))
B27: 役 務 費
B28: そ の 他
B34: 計 | D34: =SUM(D21:G33) -> 72600 | U34: =SUM(U21:X33) -> 86760
A35: 日程及び内容 | D35: 22:15～23:45 宮崎県選抜と鹿児島県選抜の合同練習 | U35: 23:00～24:30 練習試合 宮崎県選抜 ４ 対 ７ 福岡県選抜
A41: 事業の成果 | D41: 技術力・チーム連携の向上 | U41: 技術力・チーム連携の向上
A47: 記入責任者氏名（ 齋藤 和明 ） 電話番号（ 090-5288-9928 ）

Sheet 様式２－４⑨⑩事業実施・実績報告（選手強化）
A1: 様式２－⑨⑩事業実施・実績報告書
A2: 令和 ７年度 国スポ選手強化プロジェクト（①選手強化費）事業実施報告書
A4: （ アイスホッケー ）競技
A7: 事 業 名 | D7: 強化練習 ・ 遠征試合 | U7: 強化練習 ・ 遠征試合
D10: （該当するものを○で囲む） | U10: （該当するものを○で囲む）
A11: 種 別 | D11: 成年男子 ・ 成年女子 少年男子 ・ 少年女子 | U11: 成年男子 ・ 成年女子 少年男子 ・ 少年女子
D14: （該当するものを○で囲む） | U14: （該当するものを○で囲む）
A15: 期 日 | D15: 令和 ７年１１月２２日（土） | U15: 令和 ７年１２月２７（土）
A16: 場所 | B16: 会 場 | D16: スポガ久留米 | U16: スポガ久留米
B17: 宿舎名 | D17: 宿泊なし | U17: 宿泊なし
A18: 参 加 人 員 | D18: 指導者 | G18: 1 | I18: 名 | K18: 選手 | M18: 3 | O18: 名 | U18: 指導者 | X18: 0 | Z18: 名 | AB18: 選手 | AD18: 1 | AF18: 名
Q19: 計 | R19: =IF(OR(G18="",M18=""),"",SUM(G18,M18)) -> 4 | T19: 名 | AH19: 計 | AI19: =IF(OR(X18="",AD18=""),"",SUM(X18,AD18)) -> 1 | AK19: 名
A20: 支 出 の 内 訳 | B20: 科 目 | D20: 金 額 | H20: 内 訳 | U20: 金 額 | Y20: 内 訳
B21: 交 通 費 | D21: 74640 | U21: 20120
B22: 宿 泊 費 | L22: 円 | M22: × | P22: 名 | Q22: × | T22: 泊 | U22: =IF(OR(Z22="",AE22="",AI22=""),"",(Z22*AE22*AI22)) | AC22: 円 | AD22: × | AG22: 名 | AH22: × | AK22: 泊
B23: 旅行雑費 | D23: 8800 | I23: 1100 | L23: 円 | M23: × | N23: 4 | P23: 名 | Q23: × | R23: 2 | T23: 日 | U23: 2200 | Z23: 1100 | AC23: 円 | AD23: × | AE23: 1 | AG23: 名 | AH23: × | AI23: 2 | AK23: 日
B24: 駐 車 料 | U24: =IF(OR(Z24="",AE24="",AI24=""),"",(Z24*AE24*AI24))
B25: 借 用 料 | D25: 15000 | L25: 円 | M25: × | P25: 日 | U25: 2000 | AC25: 円 | AD25: × | AG25: 日
B26: 需 用 費 | U26: =IF(OR(Z26="",AF26=""),"",(Z26*AF26))
B27: 役 務 費
B28: そ の 他
B34: 計 | D34: =SUM(D21:G33) -> 98440 | U34: =SUM(U21:X33) -> 24320
A35: 日程及び内容 | D35: 22:15～23:45 宮崎選抜 ８対１ 鹿児島・久留米ｸﾗﾌﾞ | U35: 22:15～23:45 宮崎県選抜と鹿児島県選抜の合同練習
A41: 事業の成果 | D41: 技術力・チーム連携の向上 | U41: 技術力・チーム連携の向上
A47: 記入責任者氏名（ 齋藤 和明 ） 電話番号（ 090-5288-9928 ）

Sheet 様式２－４⑪⑫事業実施・実績報告（選手強化）
A1: 様式２－⑪⑫事業実施・実績報告書
A2: 令和 ７年度 国スポ選手強化プロジェクト（①選手強化費）事業実施報告書
A4: （ アイスホッケー ）競技
A7: 事 業 名 | D7: 強化練習 ・ 遠征試合 | U7: 強化練習 ・ 遠征試合
D10: （該当するものを○で囲む） | U10: （該当するものを○で囲む）
A11: 種 別 | D11: 成年男子 ・ 成年女子 少年男子 ・ 少年女子 | U11: 成年男子 ・ 成年女子 少年男子 ・ 少年女子
D14: （該当するものを○で囲む） | U14: （該当するものを○で囲む）
A15: 期 日 | D15: 令和 ８年 １月１０日（土） | U15: 令和 ８年 １月１７日（土）
A16: 場所 | B16: 会 場 | D16: えびの高原スケート場 | U16: スポガ久留米
B17: 宿舎名 | D17: 宿泊なし | U17: 宿泊なし
A18: 参 加 人 員 | D18: 指導者 | G18: 0 | I18: 名 | K18: 選手 | M18: 1 | O18: 名 | U18: 指導者 | X18: 0 | Z18: 名 | AB18: 選手 | AD18: 1 | AF18: 名
Q19: 計 | R19: =IF(OR(G18="",M18=""),"",SUM(G18,M18)) -> 1 | T19: 名 | AH19: 計 | AI19: =IF(OR(X18="",AD18=""),"",SUM(X18,AD18)) -> 1 | AK19: 名
A20: 支 出 の 内 訳 | B20: 科 目 | D20: 金 額 | H20: 内 訳 | U20: 金 額 | Y20: 内 訳
B21: 交 通 費 | D21: 4310 | U21: 17170
B22: 宿 泊 費 | L22: 円 | M22: × | P22: 名 | Q22: × | T22: 泊 | U22: =IF(OR(Z22="",AE22="",AI22=""),"",(Z22*AE22*AI22)) | AC22: 円 | AD22: × | AG22: 名 | AH22: × | AK22: 泊
B23: 旅行雑費 | D23: 200 | I23: 200 | L23: 円 | M23: × | N23: 1 | P23: 名 | Q23: × | R23: 1 | T23: 日 | U23: 2200 | Z23: 1100 | AC23: 円 | AD23: × | AE23: 1 | AG23: 名 | AH23: × | AI23: 2 | AK23: 日
B24: 駐 車 料 | U24: =IF(OR(Z24="",AE24="",AI24=""),"",(Z24*AE24*AI24))
B25: 借 用 料 | D25: 41000 | L25: 円 | M25: × | P25: 日 | U25: 2000 | AC25: 円 | AD25: × | AG25: 日
B26: 需 用 費 | U26: =IF(OR(Z26="",AF26=""),"",(Z26*AF26))
B27: 役 務 費
B28: そ の 他
B34: 計 | D34: =SUM(D21:G33) -> 45510 | U34: =SUM(U21:X33) -> 21370
A35: 日程及び内容 | D35: スケート場主催のスケート教室参加 | U35: 22:15～23:45 宮崎県選抜と鹿児島県選抜の合同練習
A41: 事業の成果 | D41: 基礎体力・技術力の向上 | U41: 技術力・チーム連携の向上
A47: 記入責任者氏名（ 齋藤 和明 ） 電話番号（ 090-5288-9928 ）

Sheet 様式２－４⑬⑭事業実施・実績報告（選手強化）
A1: 様式２－⑬⑭事業実施・実績報告書
A2: 令和 ７年度 国スポ選手強化プロジェクト（①選手強化費）事業実施報告書
A4: （ アイスホッケー ）競技
A7: 事 業 名 | D7: 強化練習 ・ 遠征試合 | U7: 強化練習 ・ 遠征試合
D10: （該当するものを○で囲む） | U10: （該当するものを○で囲む）
A11: 種 別 | D11: 成年男子 ・ 成年女子 少年男子 ・ 少年女子 | U11: 成年男子 ・ 成年女子 少年男子 ・ 少年女子
D14: （該当するものを○で囲む） | U14: （該当するものを○で囲む）
A15: 期 日 | D15: 令和 ８年 １月２４日（土）～２５日（日） | U15: 令和 ８年 １月３０日（金）
A16: 場所 | B16: 会 場 | D16: オービジョンアリーナ | U16: オービジョンアリーナ
B17: 宿舎名 | D17: ホテルＡＺ金隈 | U17: 宿泊なし
A18: 参 加 人 員 | D18: 指導者 | G18: 1 | I18: 名 | K18: 選手 | M18: 9 | O18: 名 | U18: 指導者 | X18: 0 | Z18: 名 | AB18: 選手 | AD18: 1 | AF18: 名
Q19: 計 | R19: =IF(OR(G18="",M18=""),"",SUM(G18,M18)) -> 10 | T19: 名 | AH19: 計 | AI19: =IF(OR(X18="",AD18=""),"",SUM(X18,AD18)) -> 1 | AK19: 名
A20: 支 出 の 内 訳 | B20: 科 目 | D20: 金 額 | H20: 内 訳 | U20: 金 額 | Y20: 内 訳
B21: 交 通 費 | D21: 95810 | U21: 20860
B22: 宿 泊 費 | D22: 62500 | I22: 6250 | L22: 円 | M22: × | N22: 10 | P22: 名 | Q22: × | R22: 1 | T22: 泊 | AC22: 円 | AD22: × | AG22: 名 | AH22: × | AK22: 泊
B23: 旅行雑費 | D23: 22000 | I23: 1100 | L23: 円 | M23: × | N23: 10 | P23: 名 | Q23: × | R23: 2 | T23: 日 | U23: =IF(OR(Z23="",AE23="",AI23=""),"",(Z23*AE23*AI23)) -> 2200 | Z23: 1100 | AC23: 円 | AD23: × | AE23: 1 | AG23: 名 | AH23: × | AI23: 2 | AK23: 日
B24: 駐 車 料 | U24: =IF(OR(Z24="",AE24="",AI24=""),"",(Z24*AE24*AI24))
B25: 借 用 料 | D25: 32000 | L25: 円 | M25: × | P25: 日 | U25: =IF(OR(Z25="",AF25=""),"",(Z25*AF25)) | AC25: 円 | AD25: × | AG25: 日
B26: 需 用 費 | U26: =IF(OR(Z26="",AF26=""),"",(Z26*AF26))
B27: 役 務 費
B28: そ の 他
B34: 計 | D34: =SUM(D21:G33) -> 212310 | U34: =SUM(U21:X33) -> 23060
A35: 日程及び内容 | D35: （１）１月２４日（土）19:30～21:00 福岡選抜 ７対３ 宮崎選抜 （２）１月２５日（日）7:00～8:30 単独練習 | U35: 24:30～26:00 西南学院大学の練習参加
A41: 事業の成果 | D41: 技術力・チーム連携の向上 | U41: 技術力・チーム連携の向上
A47: 記入責任者氏名（ 齋藤 和明 ） 電話番号（ 090-5288-9928 ）

Sheet 様式２－４⑮⑯事業実施・実績報告（選手強化）
A1: 様式２－⑮⑯事業実施・実績報告書
A2: 令和 ７年度 国スポ選手強化プロジェクト（①選手強化費）事業実施報告書
A4: （ アイスホッケー ）競技
A7: 事 業 名 | D7: 強化練習 ・ 遠征試合 | U7: 強化練習 ・ 遠征試合
D10: （該当するものを○で囲む） | U10: （該当するものを○で囲む）
A11: 種 別 | D11: 成年男子 ・ 成年女子 少年男子 ・ 少年女子 | U11: 成年男子 ・ 成年女子 少年男子 ・ 少年女子
D14: （該当するものを○で囲む） | U14: （該当するものを○で囲む）
A15: 期 日 | D15: 令和 ８年 ２月７日（土） | U15: 令和 ８年 ２月２１日（土）
A16: 場所 | B16: 会 場 | D16: 熊本アクアドーム | U16: 熊本アクアドーム
B17: 宿舎名 | D17: 宿泊なし | U17: 宿泊なし
A18: 参 加 人 員 | D18: 指導者 | G18: 0 | I18: 名 | K18: 選手 | M18: 2 | O18: 名 | U18: 指導者 | X18: 0 | Z18: 名 | AB18: 選手 | AD18: 2 | AF18: 名
Q19: 計 | R19: =IF(OR(G18="",M18=""),"",SUM(G18,M18)) -> 2 | T19: 名 | AH19: 計 | AI19: =IF(OR(X18="",AD18=""),"",SUM(X18,AD18)) -> 2 | AK19: 名
A20: 支 出 の 内 訳 | B20: 科 目 | D20: 金 額 | H20: 内 訳 | U20: 金 額 | Y20: 内 訳
B21: 交 通 費 | D21: 23360 | U21: 26710
B22: 宿 泊 費 | L22: 円 | M22: × | P22: 名 | Q22: × | T22: 泊 | U22: =IF(OR(Z22="",AE22="",AI22=""),"",(Z22*AE22*AI22)) | AC22: 円 | AD22: × | AG22: 名 | AH22: × | AK22: 泊
B23: 旅行雑費 | D23: 4400 | I23: 1100 | L23: 円 | M23: × | N23: 2 | P23: 名 | Q23: × | R23: 2 | T23: 日 | U23: =IF(OR(Z23="",AE23="",AI23=""),"",(Z23*AE23*AI23)) -> 4400 | Z23: 1100 | AC23: 円 | AD23: × | AE23: 2 | AG23: 名 | AH23: × | AI23: 2 | AK23: 日
B24: 駐 車 料 | U24: =IF(OR(Z24="",AE24="",AI24=""),"",(Z24*AE24*AI24))
B25: 借 用 料 | L25: 円 | M25: × | P25: 日 | U25: 35750 | AC25: 円 | AD25: × | AG25: 日
B26: 需 用 費 | U26: =IF(OR(Z26="",AF26=""),"",(Z26*AF26))
B27: 役 務 費
B28: そ の 他
B34: 計 | D34: =SUM(D21:G33) -> 27760 | U34: =SUM(U21:X33) -> 66860
A35: 日程及び内容 | D35: 19:30～22:00 第44回熊日盾杯アイスホッケー大会 熊本ﾌﾞﾙｰｴﾝｼﾞｪﾙ １ 対 ２ 宮崎・鹿児島選抜 | U35: 20:30～22:00 第44回熊日盾杯アイスホッケー大会 熊本スコアJr ７ 対 ３ 宮崎・鹿児島選抜
A41: 事業の成果 | D41: 技術力・チーム連携の向上 | U41: 技術力・チーム連携の向上
A47: 記入責任者氏名（ 齋藤 和明 ） 電話番号（ 090-5288-9928 ）

Sheet 様式２－４⑰事業実績・実績報告（選手強化）
A1: 様式２－⑰事業実施・実績報告書
A2: 令和 ７年度 国スポ選手強化プロジェクト（①選手強化費）事業実施報告書
A4: （ アイスホッケー ）競技
A7: 事 業 名 | D7: 強化練習 ・ 遠征試合 | U7: 強化練習 ・ 遠征試合
D10: （該当するものを○で囲む） | U10: （該当するものを○で囲む）
A11: 種 別 | D11: 成年男子 ・ 成年女子 少年男子 ・ 少年女子 | U11: 成年男子 ・ 成年女子 少年男子 ・ 少年女子
D14: （該当するものを○で囲む） | U14: （該当するものを○で囲む）
A15: 期 日 | D15: 令和 ８年 ２月２８日（土）～３月 １日（日） | U15: 令和 年 月 日（ ）
A16: 場所 | B16: 会 場 | D16: 福岡アクシオン
B17: 宿舎名 | D17: ホテルＡＺ篠栗
A18: 参 加 人 員 | D18: 指導者 | G18: 0 | I18: 名 | K18: 選手 | M18: 3 | O18: 名 | U18: 指導者 | Z18: 名 | AB18: 選手 | AF18: 名
Q19: 計 | R19: =IF(OR(G18="",M18=""),"",SUM(G18,M18)) -> 3 | T19: 名 | AH19: 計 | AI19: =IF(OR(X18="",AD18=""),"",SUM(X18,AD18)) | AK19: 名
A20: 支 出 の 内 訳 | B20: 科 目 | D20: 金 額 | H20: 内 訳 | U20: 金 額 | Y20: 内 訳
B21: 交 通 費 | D21: 39460
B22: 宿 泊 費 | D22: 18750 | I22: 6250 | L22: 円 | M22: × | N22: 3 | P22: 名 | Q22: × | R22: 1 | T22: 泊 | U22: =IF(OR(Z22="",AE22="",AI22=""),"",(Z22*AE22*AI22)) | AC22: 円 | AD22: × | AG22: 名 | AH22: × | AK22: 泊
B23: 旅行雑費 | D23: 6600 | I23: 1100 | L23: 円 | M23: × | N23: 3 | P23: 名 | Q23: × | R23: 2 | T23: 日 | U23: =IF(OR(Z23="",AE23="",AI23=""),"",(Z23*AE23*AI23)) | AC23: 円 | AD23: × | AG23: 名 | AH23: × | AK23: 日
B24: 駐 車 料 | U24: =IF(OR(Z24="",AE24="",AI24=""),"",(Z24*AE24*AI24))
B25: 借 用 料 | D25: 83000 | L25: 円 | M25: × | P25: 日 | U25: =IF(OR(Z25="",AF25=""),"",(Z25*AF25)) | AC25: 円 | AD25: × | AG25: 日
B26: 需 用 費 | U26: =IF(OR(Z26="",AF26=""),"",(Z26*AF26))
B27: 役 務 費
B28: そ の 他
B34: 計 | D34: =SUM(D21:G33) -> 147810 | U34: =SUM(U21:X33) -> 0
A35: 日程及び内容 | D35: （１）２月２８日（土） 13:50～ 宮崎鹿児島選抜 ３ 対 ９ 長崎選抜 （２）３月 １日（日） 17:20～ 宮崎鹿児島選抜 １ 対 ８ 佐賀選抜
A41: 事業の成果 | D41: 技術力・チーム連携の向上
A47: 記入責任者氏名（ 齋藤 和明 ） 電話番号（ 090-5288-9928 ）

Sheet 様式２－５①事業別参加者名簿（選手強化）
A1: 様式２－５①事業別参加者名簿
B3: 令和 | C3: 7 | D3: 年度 | E3: 選手強化費 | I3: 参加者名簿
B5: 団体名 | D5: アイスホッケー連盟
A6: 【事業実施日】 | C6: 令和 ７年 ５月２４日
A7: 番号 | B7: 監督・選手別 | D7: 氏 名 | G7: 年齢･学年 | H7: 宿泊対象者
H8: 月 日 | I8: 月 日 | J8: 月 日
A9: 1 | B9: 選手 | D9: 長友 繁 | G9: 48
A10: 2 | B10: 選手 | D10: 中村 里惟 | G10: 26
A11: 3 | B11: 選手 | D11: 蛯原 智仁 | G11: 25
A12: 4
A13: 5
A14: 6
A15: 7
A16: 8
A17: 9
A18: 10
A19: 11
A20: 12
A21: 13
A22: 14
A23: 15
... A36: 28
A37: 記入責任者氏名（ 齋藤 豊光 ） 電話番号（ 090-8224-0842 ）
A38: ※ 参加者名簿については、事業実施日ごとに作成すること。
A39: ※ 宿泊費の支出があった者については、宿泊対象者の欄に○を付けること。
A40: ※ 参加者名簿様式は、競技団体の様式でも可。ただし、宿泊対象者がわかるように記載すること。

Sheet 様式２－５②事業別参加者名簿（選手強化）
A1: 様式２－５②事業別参加者名簿
B3: 令和 | C3: 7 | D3: 年度 | E3: 選手強化費 | I3: 参加者名簿
B5: 団体名 | D5: アイスホッケー連盟
A6: 【事業実施日】 | C6: 令和 ７ 年６月１４日
A7: 番号 | B7: 監督・選手別 | D7: 氏 名 | G7: 年齢･学年 | H7: 宿泊対象者
H8: 月 日 | I8: 月 日 | J8: 月 日
A9: 1 | B9: 監督 | D9: 齋藤 豊光 | G9: 67
A10: 2 | B10: 選手 | D10: 髙見 翼人 | G10: 34
A11: 3 | B11: 選手 | D11: 蛯原 智仁 | G11: 25
A12: 4 | B12: 選手 | D12: 中村 里惟 | G12: 26
A13: 5
A14: 6
A15: 7
A16: 8
A17: 9
A18: 10
A19: 11
A20: 12
A21: 13
A22: 14
A23: 15
A24: 16
... A36: 28
A37: 記入責任者氏名（ 齋藤 豊光 ） 電話番号（ 090-8224-0842 ）
A38: ※ 参加者名簿については、事業実施日ごとに作成すること。
A39: ※ 宿泊費の支出があった者については、宿泊対象者の欄に○を付けること。
A40: ※ 参加者名簿様式は、競技団体の様式でも可。ただし、宿泊対象者がわかるように記載すること。

Sheet 様式２－５③事業別参加者名簿（選手強化）
A1: 様式２－５③事業別参加者名簿
B3: 令和 | C3: 7 | D3: 年度 | E3: 選手強化費 | I3: 参加者名簿
B5: 団体名 | D5: アイスホッケー連盟
A6: 【事業実施日】 | C6: 令和 ７ 年 ８ 月２３日
A7: 番号 | B7: 監督・選手別 | D7: 氏 名 | G7: 年齢･学年 | H7: 宿泊対象者
H8: 月 日 | I8: 月 日 | J8: 月 日
A9: 1 | B9: 監督 | D9: 齋藤 豊光 | G9: 67
A10: 2 | B10: 選手 | D10: 髙見 翼人 | G10: 34
A11: 3 | B11: 選手 | D11: 蛯原 智仁 | G11: 25
A12: 4 | B12: 選手 | D12: 中村 里惟 | G12: 26
A13: 5
A14: 6
A15: 7
A16: 8
A17: 9
A18: 10
A19: 11
A20: 12
A21: 13
A22: 14
A23: 15
A24: 16
... A36: 28
A37: 記入責任者氏名（ 齋藤 豊光 ） 電話番号（ 090-8224-0842 ）
A38: ※ 参加者名簿については、事業実施日ごとに作成すること。
A39: ※ 宿泊費の支出があった者については、宿泊対象者の欄に○を付けること。
A40: ※ 参加者名簿様式は、競技団体の様式でも可。ただし、宿泊対象者がわかるように記載すること。

Sheet 様式２－５④事業別参加者名簿（選手強化）
A1: 様式２－５④事業別参加者名簿
B3: 令和 | C3: 7 | D3: 年度 | E3: 選手強化費 | I3: 参加者名簿
B5: 団体名 | D5: アイスホッケー連盟
A6: 【事業実施日】 | C6: 令和 ７ 年 ９ 月１３日
A7: 番号 | B7: 監督・選手別 | D7: 氏 名 | G7: 年齢･学年 | H7: 宿泊対象者
H8: 月 日 | I8: 月 日 | J8: 月 日
A9: 1 | B9: 監督 | D9: 齋藤 豊光 | G9: 67
A10: 2 | B10: 選手 | D10: 髙見 翼人 | G10: 34
A11: 3 | B11: 選手 | D11: 宮城 将嗣 | G11: 32
A12: 4 | B12: 選手 | D12: 中村 里惟 | G12: 26
A13: 5
A14: 6
A15: 7
A16: 8
A17: 9
A18: 10
A19: 11
A20: 12
A21: 13
A22: 14
A23: 15
A24: 16
... A36: 28
A37: 記入責任者氏名（ 齋藤 豊光 ） 電話番号（ 090-8224-0842 ）
A38: ※ 参加者名簿については、事業実施日ごとに作成すること。
A39: ※ 宿泊費の支出があった者については、宿泊対象者の欄に○を付けること。
A40: ※ 参加者名簿様式は、競技団体の様式でも可。ただし、宿泊対象者がわかるように記載すること。

Sheet 様式２－５➄事業別参加者名簿（選手強化）
A1: 様式２－５➄事業別参加者名簿
B3: 令和 | C3: 7 | D3: 年度 | E3: 選手強化費 | I3: 参加者名簿
B5: 団体名 | D5: アイスホッケー連盟
A6: 【事業実施日】 | C6: 令和 ７ 年 ９ 月２７日
A7: 番号 | B7: 監督・選手別 | D7: 氏 名 | G7: 年齢･学年 | H7: 宿泊対象者
H8: 月 日 | I8: 月 日 | J8: 月 日
A9: 1 | B9: 監督 | D9: 齋藤 豊光 | G9: 67
A10: 2 | B10: コーチ | D10: 谷脇 優二 | G10: 64
A11: 3 | B11: 選手 | D11: 髙見 翼人 | G11: 34
A12: 4 | B12: 選手 | D12: 蛯原 智仁 | G12: 25
A13: 5
A14: 6
A15: 7
A16: 8
A17: 9
A18: 10
A19: 11
A20: 12
A21: 13
A22: 14
A23: 15
A24: 16
... A36: 28
A37: 記入責任者氏名（ 齋藤 豊光 ） 電話番号（ 090-8224-0842 ）
A38: ※ 参加者名簿については、事業実施日ごとに作成すること。
A39: ※ 宿泊費の支出があった者については、宿泊対象者の欄に○を付けること。
A40: ※ 参加者名簿様式は、競技団体の様式でも可。ただし、宿泊対象者がわかるように記載すること。

Sheet 様式２－５⑥事業別参加者名簿（選手強化）
A1: 様式２－５⑥事業別参加者名簿
B3: 令和 | C3: 7 | D3: 年度 | E3: 選手強化費 | I3: 参加者名簿
B5: 団体名 | D5: アイスホッケー連盟
A6: 【事業実施日】 | C6: 令和 ７ 年 １０ 月 ４ 日
A7: 番号 | B7: 監督・選手別 | D7: 氏 名 | G7: 年齢･学年 | H7: 宿泊対象者
H8: 月 日 | I8: 月 日 | J8: 月 日
A9: 1 | B9: 監督 | D9: 齋藤 豊光 | G9: 67
A10: 2 | B10: 選手 | D10: 髙見 翼人 | G10: 34
A11: 3
A12: 4
A13: 5
A14: 6
A15: 7
A16: 8
A17: 9
A18: 10
A19: 11
A20: 12
A21: 13
A22: 14
... A36: 28
A37: 記入責任者氏名（ 齋藤 豊光 ） 電話番号（ 090-8224-0842 ）
A38: ※ 参加者名簿については、事業実施日ごとに作成すること。
A39: ※ 宿泊費の支出があった者については、宿泊対象者の欄に○を付けること。
A40: ※ 参加者名簿様式は、競技団体の様式でも可。ただし、宿泊対象者がわかるように記載すること。

Sheet 様式２－５⑦事業別参加者名簿（選手強化）
A1: 様式２－５⑦事業別参加者名簿
B3: 令和 | C3: 7 | D3: 年度 | E3: 選手強化費 | I3: 参加者名簿
B5: 団体名 | D5: アイスホッケー連盟
A6: 【事業実施日】 | C6: 令和 ７ 年 １０ 月 ２５ 日
A7: 番号 | B7: 監督・選手別 | D7: 氏 名 | G7: 年齢･学年 | H7: 宿泊対象者
H8: 月 日 | I8: 月 日 | J8: 月 日
A9: 1 | B9: 監督 | D9: 齋藤 豊光 | G9: 67
A10: 2 | B10: 選手 | D10: 髙見 翼人 | G10: 34
A11: 3 | B11: 選手 | D11: 蛯原 智仁 | G11: 25
A12: 4
A13: 5
A14: 6
A15: 7
A16: 8
A17: 9
A18: 10
A19: 11
A20: 12
A21: 13
A22: 14
A23: 15
... A36: 28
A37: 記入責任者氏名（ 齋藤 豊光 ） 電話番号（ 090-8224-0842 ）
A38: ※ 参加者名簿については、事業実施日ごとに作成すること。
A39: ※ 宿泊費の支出があった者については、宿泊対象者の欄に○を付けること。
A40: ※ 参加者名簿様式は、競技団体の様式でも可。ただし、宿泊対象者がわかるように記載すること。

Sheet 様式２－５⑧事業別参加者名簿（選手強化）
A1: 様式２－５⑧事業別参加者名簿
B3: 令和 | C3: 7 | D3: 年度 | E3: 選手強化費 | I3: 参加者名簿
B5: 団体名 | D5: アイスホッケー連盟
A6: 【事業実施日】 | C6: 令和 ７ 年 １１ 月 ８ 日
A7: 番号 | B7: 監督・選手別 | D7: 氏 名 | G7: 年齢･学年 | H7: 宿泊対象者
H8: 月 日 | I8: 月 日 | J8: 月 日
A9: 1 | B9: 監督 | D9: 齋藤 豊光 | G9: 67
A10: 2 | B10: 選手 | D10: 髙見 翼人 | G10: 34
A11: 3 | B11: 選手 | D11: 中村 里惟 | G11: 26
A12: 4 | B12: 選手 | D12: 蛯原 智仁 | G12: 25
A13: 5
A14: 6
A15: 7
A16: 8
A17: 9
A18: 10
A19: 11
A20: 12
A21: 13
A22: 14
A23: 15
A24: 16
... A36: 28
A37: 記入責任者氏名（ 齋藤 豊光 ） 電話番号（ 090-8224-0842 ）
A38: ※ 参加者名簿については、事業実施日ごとに作成すること。
A39: ※ 宿泊費の支出があった者については、宿泊対象者の欄に○を付けること。
A40: ※ 参加者名簿様式は、競技団体の様式でも可。ただし、宿泊対象者がわかるように記載すること。

Sheet 様式２－５⑨事業別参加者名簿（選手強化）
A1: 様式２－５⑨事業別参加者名簿
B3: 令和 | C3: 7 | D3: 年度 | E3: 選手強化費 | I3: 参加者名簿
B5: 団体名 | D5: アイスホッケー連盟
A6: 【事業実施日】 | C6: 令和 ７ 年 １１ 月 ２２ 日
A7: 番号 | B7: 監督・選手別 | D7: 氏 名 | G7: 年齢･学年 | H7: 宿泊対象者
H8: 月 日 | I8: 月 日 | J8: 月 日
A9: 1 | B9: 監督 | D9: 齋藤 豊光 | G9: 67
A10: 2 | B10: 選手 | D10: 髙見 翼人 | G10: 34
A11: 3 | B11: 選手 | D11: 中村 里惟 | G11: 26
A12: 4 | B12: 選手 | D12: 蛯原 智仁 | G12: 25
A13: 5
A14: 6
A15: 7
A16: 8
A17: 9
A18: 10
A19: 11
A20: 12
A21: 13
A22: 14
A23: 15
A24: 16
... A36: 28
A37: 記入責任者氏名（ 齋藤 豊光 ） 電話番号（ 090-8224-0842 ）
A38: ※ 参加者名簿については、事業実施日ごとに作成すること。
A39: ※ 宿泊費の支出があった者については、宿泊対象者の欄に○を付けること。
A40: ※ 参加者名簿様式は、競技団体の様式でも可。ただし、宿泊対象者がわかるように記載すること。

Sheet 様式２－５⑩事業別参加者名簿（選手強化）
A1: 様式２－５⑩事業別参加者名簿
B3: 令和 | C3: 7 | D3: 年度 | E3: 選手強化費 | I3: 参加者名簿
B5: 団体名 | D5: アイスホッケー連盟
A6: 【事業実施日】 | C6: 令和 ７ 年 １２ 月 ２７ 日
A7: 番号 | B7: 監督・選手別 | D7: 氏 名 | G7: 年齢･学年 | H7: 宿泊対象者
H8: 月 日 | I8: 月 日 | J8: 月 日
A9: 1 | B9: 選手 | D9: 中村 里惟 | G9: 26
A10: 2
A11: 3
A12: 4
A13: 5
A14: 6
A15: 7
A16: 8
A17: 9
A18: 10
A19: 11
A20: 12
A21: 13
... A36: 28
A37: 記入責任者氏名（ 齋藤 豊光 ） 電話番号（ 090-8224-0842 ）
A38: ※ 参加者名簿については、事業実施日ごとに作成すること。
A39: ※ 宿泊費の支出があった者については、宿泊対象者の欄に○を付けること。
A40: ※ 参加者名簿様式は、競技団体の様式でも可。ただし、宿泊対象者がわかるように記載すること。

Sheet 様式２－５⑪事業別参加者名簿（選手強化）
A1: 様式２－５⑪事業別参加者名簿
B3: 令和 | C3: 7 | D3: 年度 | E3: 選手強化費 | I3: 参加者名簿
B5: 団体名 | D5: アイスホッケー連盟
A6: 【事業実施日】 | C6: 令和 ８ 年 １ 月 １０ 日
A7: 番号 | B7: 監督・選手別 | D7: 氏 名 | G7: 年齢･学年 | H7: 宿泊対象者
H8: 月 日 | I8: 月 日 | J8: 月 日
A9: 1 | B9: 選手 | D9: 蛯原 智仁 | G9: 25
A10: 2
A11: 3
A12: 4
A13: 5
A14: 6
A15: 7
A16: 8
A17: 9
A18: 10
A19: 11
A20: 12
A21: 13
... A36: 28
A37: 記入責任者氏名（ 齋藤 豊光 ） 電話番号（ 090-8224-0842 ）
A38: ※ 参加者名簿については、事業実施日ごとに作成すること。
A39: ※ 宿泊費の支出があった者については、宿泊対象者の欄に○を付けること。
A40: ※ 参加者名簿様式は、競技団体の様式でも可。ただし、宿泊対象者がわかるように記載すること。

Sheet 様式２－５⑫事業別参加者名簿（選手強化）
A1: 様式２－５⑫事業別参加者名簿
B3: 令和 | C3: 7 | D3: 年度 | E3: 選手強化費 | I3: 参加者名簿
B5: 団体名 | D5: アイスホッケー連盟
A6: 【事業実施日】 | C6: 令和 ８ 年 １ 月 １７ 日
A7: 番号 | B7: 監督・選手別 | D7: 氏 名 | G7: 年齢･学年 | H7: 宿泊対象者
H8: 月 日 | I8: 月 日 | J8: 月 日
A9: 1 | B9: 選手 | D9: 中村 里惟 | G9: 26
A10: 2
A11: 3
A12: 4
A13: 5
A14: 6
A15: 7
A16: 8
A17: 9
A18: 10
A19: 11
A20: 12
A21: 13
... A36: 28
A37: 記入責任者氏名（ 齋藤 豊光 ） 電話番号（ 090-8224-0842 ）
A38: ※ 参加者名簿については、事業実施日ごとに作成すること。
A39: ※ 宿泊費の支出があった者については、宿泊対象者の欄に○を付けること。
A40: ※ 参加者名簿様式は、競技団体の様式でも可。ただし、宿泊対象者がわかるように記載すること。

Sheet 様式２－５⑬事業別参加者名簿（選手強化）
A1: 様式２－５⑬事業別参加者名簿
B3: 令和 | C3: 7 | D3: 年度 | E3: 選手強化費 | I3: 参加者名簿
B5: 団体名 | D5: アイスホッケー連盟
A6: 【事業実施日】 | C6: 令和 ８ 年 １ 月２４日～２５日
A7: 番号 | B7: 監督・選手別 | D7: 氏 名 | G7: 年齢･学年 | H7: 宿泊対象者
H8: 46046 | I8: 月 日 | J8: 月 日
A9: 1 | B9: 選手 | D9: 蛯原 智仁 | G9: 25 | H9: 〇
A10: 2 | B10: 選手 | D10: 中村 里惟 | G10: 26 | H10: 〇
A11: 3 | B11: 選手 | D11: 山田 幸治 | G11: 45 | H11: 〇
A12: 4 | B12: 選手 | D12: 髙見 翼人 | G12: 35 | H12: 〇
A13: 5 | B13: 選手 | D13: 松本 紘煕 | G13: 32 | H13: 〇
A14: 6 | B14: コーチ | D14: 日髙 雅壮 | G14: 57 | H14: 〇
A15: 7 | B15: 選手 | D15: 小林 大祐 | G15: 32 | H15: 〇
A16: 8 | B16: 選手 | D16: 新森 康弘 | G16: 43 | H16: 〇
A17: 9 | B17: 選手 | D17: 児玉 恵吾 | G17: 40 | H17: 〇
A18: 10 | B18: 選手 | D18: 宮城 将嗣 | G18: 33 | H18: 〇
A19: 11
A20: 12
A21: 13
A22: 14
A23: 15
A24: 16
A25: 17
A26: 18
A27: 19
A28: 20
A29: 21
A30: 22
... A36: 28
A37: 記入責任者氏名（ 齋藤 豊光 ） 電話番号（ 090-8224-0842 ）
A38: ※ 参加者名簿については、事業実施日ごとに作成すること。
A39: ※ 宿泊費の支出があった者については、宿泊対象者の欄に○を付けること。
A40: ※ 参加者名簿様式は、競技団体の様式でも可。ただし、宿泊対象者がわかるように記載すること。

Sheet 様式２－５⑭事業別参加者名簿（選手強化）
A1: 様式２－５⑭事業別参加者名簿
B3: 令和 | C3: 7 | D3: 年度 | E3: 選手強化費 | I3: 参加者名簿
B5: 団体名 | D5: アイスホッケー連盟
A6: 【事業実施日】 | C6: 令和 ８ 年 １ 月３０日
A7: 番号 | B7: 監督・選手別 | D7: 氏 名 | G7: 年齢･学年 | H7: 宿泊対象者
H8: 月 日 | I8: 月 日 | J8: 月 日
A9: 1 | B9: 選手 | D9: 蛯原 智仁 | G9: 25
A10: 2
A11: 3
A12: 4
A13: 5
A14: 6
A15: 7
A16: 8
A17: 9
A18: 10
A19: 11
A20: 12
A21: 13
... A36: 28
A37: 記入責任者氏名（ 齋藤 豊光 ） 電話番号（ 090-8224-0842 ）
A38: ※ 参加者名簿については、事業実施日ごとに作成すること。
A39: ※ 宿泊費の支出があった者については、宿泊対象者の欄に○を付けること。
A40: ※ 参加者名簿様式は、競技団体の様式でも可。ただし、宿泊対象者がわかるように記載すること。

Sheet 様式２－５⑮事業別参加者名簿（選手強化）
A1: 様式２－５⑮事業別参加者名簿
B3: 令和 | C3: 7 | D3: 年度 | E3: 選手強化費 | I3: 参加者名簿
B5: 団体名 | D5: アイスホッケー連盟
A6: 【事業実施日】 | C6: 令和 ８ 年 ２ 月 ７ 日
A7: 番号 | B7: 監督・選手別 | D7: 氏 名 | G7: 年齢･学年 | H7: 宿泊対象者
H8: 月 日 | I8: 月 日 | J8: 月 日
A9: 1 | B9: 選手 | D9: 宮城 将嗣 | G9: 33
A10: 2 | B10: 選手 | D10: 山田 幸司 | G10: 44
A11: 3
A12: 4
A13: 5
A14: 6
A15: 7
A16: 8
A17: 9
A18: 10
A19: 11
A20: 12
A21: 13
A22: 14
... A36: 28
A37: 記入責任者氏名（ 齋藤 豊光 ） 電話番号（ 090-8224-0842 ）
A38: ※ 参加者名簿については、事業実施日ごとに作成すること。
A39: ※ 宿泊費の支出があった者については、宿泊対象者の欄に○を付けること。
A40: ※ 参加者名簿様式は、競技団体の様式でも可。ただし、宿泊対象者がわかるように記載すること。

Sheet 様式２－５⑯事業別参加者名簿（選手強化）
A1: 様式２－５⑯事業別参加者名簿
B3: 令和 | C3: 7 | D3: 年度 | E3: 選手強化費 | I3: 参加者名簿
B5: 団体名 | D5: アイスホッケー連盟
A6: 【事業実施日】 | C6: 令和 ８ 年 ２ 月 ２１ 日
A7: 番号 | B7: 監督・選手別 | D7: 氏 名 | G7: 年齢･学年 | H7: 宿泊対象者
H8: 月 日 | I8: 月 日 | J8: 月 日
A9: 1 | B9: 選手 | D9: 蛯原 智仁 | G9: 25
A10: 2 | B10: 選手 | D10: 山田 幸司 | G10: 44
A11: 3
A12: 4
A13: 5
A14: 6
A15: 7
A16: 8
A17: 9
A18: 10
A19: 11
A20: 12
A21: 13
A22: 14
... A36: 28
A37: 記入責任者氏名（ 齋藤 豊光 ） 電話番号（ 090-8224-0842 ）
A38: ※ 参加者名簿については、事業実施日ごとに作成すること。
A39: ※ 宿泊費の支出があった者については、宿泊対象者の欄に○を付けること。
A40: ※ 参加者名簿様式は、競技団体の様式でも可。ただし、宿泊対象者がわかるように記載すること。

Sheet 様式２－５⑰事業別参加者名簿（選手強化）
A1: 様式２－５⑰事業別参加者名簿
B3: 令和 | C3: 7 | D3: 年度 | E3: 選手強化費 | I3: 参加者名簿
B5: 団体名 | D5: アイスホッケー連盟
A6: 【事業実施日】 | C6: 令和 ８ 年２月２８日～３月１日
A7: 番号 | B7: 監督・選手別 | D7: 氏 名 | G7: 年齢･学年 | H7: 宿泊対象者
H8: 46081 | I8: 月 日 | J8: 月 日
A9: 1 | B9: 選手 | D9: 山田 幸司 | G9: 44 | H9: 〇
A10: 2 | B10: 選手 | D10: 松本 紘煕 | G10: 32 | H10: 〇
A11: 3 | B11: 選手 | D11: 宮城 将嗣 | G11: 33 | H11: 〇
A12: 4
A13: 5
A14: 6
A15: 7
A16: 8
A17: 9
A18: 10
A19: 11
A20: 12
A21: 13
A22: 14
A23: 15
... A36: 28
A37: 記入責任者氏名（ 齋藤 豊光 ） 電話番号（ 090-8224-0842 ）
A38: ※ 参加者名簿については、事業実施日ごとに作成すること。
A39: ※ 宿泊費の支出があった者については、宿泊対象者の欄に○を付けること。
A40: ※ 参加者名簿様式は、競技団体の様式でも可。ただし、宿泊対象者がわかるように記載すること。

Sheet 様式２－６①事業別領収書１（選手強化）
A1: 様式２－６①事業別領収書１
G3: 令和 | J3: 7 | L3: 年度 | P3: 選手強化費 領収書１
A5: 団体名 | G5: 宮崎県アイスホッケー連盟
AC7: 作成者名（ 齋藤 豊光 ）
A8: No | C8: 氏 名 | J8: 期日 | N8: 交 通 | T8: 支 払 額 | AF8: 受領日 | AP8: 受領 サイン
N9: 区 間 | T9: 交通費 | X9: 宿泊費 | AB9: 雑費
A10: 1 | C10: 長友 繁 | J10: 45801 | N10: 航空機・ﾊﾞｽ | T10: 21020 | X10: 0 | AB10: 2200 | AF10: 45801
N11: 電車・車(640)㎞
N12: 宮崎西～福岡
A13: 2 | C13: 中村 里惟 | J13: 45801 | N13: 航空機・ﾊﾞｽ | T13: 20290 | X13: 0 | AB13: 2200 | AF13: 45801
N14: 電車・車(600)㎞
N15: 宮崎～福岡
A16: 3 | C16: 蛯原 智仁 | J16: 45801 | N16: 航空機・ﾊﾞｽ | T16: 20390 | X16: 0 | AB16: 2200 | AF16: 45801
N17: 電車・車(600)㎞
N18: 宮崎～福岡
A19: 4 | X19: 0
A22: 5 | X22: 0
A25: 6 | X25: 0
A28: 7 | X28: 0
A31: 8
A34: 9
A37: 10
P40: 合 計 | T40: =SUM(T10:W39) -> 61700 | X40: =SUM(X10:AA39) -> 0 | AB40: =SUM(AB10:AE39) -> 6600 | AF40: 旅費合計 | AL40: =SUM(T40:AE40) -> 68300
A41: 記入責任者氏名( 齋藤 豊光 ) | AB41: 電話番号(０９０－８２２４－０８４２ )
A42: 記入上の注意
A43: ① 金額欄は、同額であっても「同上」、「〃」で記入せず、必ず金額を記入のこと。
A44: ② 受領した本人が自署または押印すること。
A45: 航空機利用の場合、領収書（利用者氏名・利用区間・便名・搭乗日が記載されているもの）を添付すること。
A46: ③ 旅行業者等に交通手段・宿泊等を一括手配（依頼）し利用した場合は、旅行業者の領収書を添付する。
A47: 但し、内訳として交通費と宿泊費の明細を添付のこと。
A48: ④ 交通費は、最も経済的な通常の経路、方法により算出すること。
A49: ⑤ 自家用車を利用した場合、出発地と目的地間の最短距離(㎞ 端数切捨)に１７円を乗じた額とする。
A50: また、有料道路利用の場合は、領収書または利用証明書を添付すること。
A51: ⑥ 加盟団体等が定めた取扱等がある場合は、その取扱等により計算した額とすること。但し、本会の基準で計算した額を
A52: 上限とし、超過する場合は補助対象外とする。(注) この場合は、加盟団体等が定めた取扱等を提出すること。
A53: ⑦ 公共交通機関を利用した場合は、利用区間名(バス停、駅)を記入すること。

Sheet 様式２－６②事業別領収書１（選手強化）
A1: 様式２－６②事業別領収書１
G3: 令和 | J3: 7 | L3: 年度 | P3: 選手強化費 領収書１
A5: 団体名 | G5: 宮崎県アイスホッケー連盟
AC7: 作成者名（ 齋藤 豊光 ）
A8: No | C8: 氏 名 | J8: 期日 | N8: 交 通 | T8: 支 払 額 | AF8: 受領日 | AP8: 受領 サイン
N9: 区 間 | T9: 交通費 | X9: 宿泊費 | AB9: 雑費
A10: 1 | C10: 齋藤 豊光 | J10: 45822 | N10: 航空機・ﾊﾞｽ | T10: 20560 | X10: 0 | AB10: 2200 | AF10: 45822
N11: 電車・車(640)㎞
N12: 宮崎～福岡
A13: 2 | C13: 髙見 翼人 | J13: 45822 | N13: 航空機・ﾊﾞｽ | T13: 17480 | X13: 0 | AB13: 2200 | AF13: 45822
N14: 電車・車(540)㎞
N15: 都城～福岡
A16: 3 | C16: 蛯原 智仁 | J16: 45822 | N16: 航空機・ﾊﾞｽ | T16: 19110 | X16: 0 | AB16: 2200 | AF16: 45822
N17: 電車・車(600)㎞
N18: 宮崎～福岡
A19: 4 | C19: 中村 里惟 | J19: 45822 | N19: 航空機・ﾊﾞｽ | T19: 19390 | X19: 0 | AB19: 2200 | AF19: 45822
N20: 電車・車(600)㎞
N21: 宮崎～福岡
A22: 5 | X22: 0
A25: 6 | X25: 0
A28: 7 | X28: 0
A31: 8
A34: 9
A37: 10
P40: 合 計 | T40: =SUM(T10:W39) -> 76540 | X40: =SUM(X10:AA39) -> 0 | AB40: =SUM(AB10:AE39) -> 8800 | AF40: 旅費合計 | AL40: =SUM(T40:AE40) -> 85340
A41: 記入責任者氏名( 齋藤 豊光 ) | AB41: 電話番号(０９０－８２２４－０８４２ )
A42: 記入上の注意
A43: ① 金額欄は、同額であっても「同上」、「〃」で記入せず、必ず金額を記入のこと。
A44: ② 受領した本人が自署または押印すること。
A45: 航空機利用の場合、領収書（利用者氏名・利用区間・便名・搭乗日が記載されているもの）を添付すること。
A46: ③ 旅行業者等に交通手段・宿泊等を一括手配（依頼）し利用した場合は、旅行業者の領収書を添付する。
A47: 但し、内訳として交通費と宿泊費の明細を添付のこと。
A48: ④ 交通費は、最も経済的な通常の経路、方法により算出すること。
A49: ⑤ 自家用車を利用した場合、出発地と目的地間の最短距離(㎞ 端数切捨)に１７円を乗じた額とする。
A50: また、有料道路利用の場合は、領収書または利用証明書を添付すること。
A51: ⑥ 加盟団体等が定めた取扱等がある場合は、その取扱等により計算した額とすること。但し、本会の基準で計算した額を
A52: 上限とし、超過する場合は補助対象外とする。(注) この場合は、加盟団体等が定めた取扱等を提出すること。
A53: ⑦ 公共交通機関を利用した場合は、利用区間名(バス停、駅)を記入すること。

Sheet 様式２－６③事業別領収書１（選手強化）
A1: 様式２－６③事業別領収書１
G3: 令和 | J3: 7 | L3: 年度 | P3: 選手強化費 領収書１
A5: 団体名 | G5: 宮崎県アイスホッケー連盟
AC7: 作成者名（ 齋藤 豊光 ）
A8: No | C8: 氏 名 | J8: 期日 | N8: 交 通 | T8: 支 払 額 | AF8: 受領日 | AP8: 受領 サイン
N9: 区 間 | T9: 交通費 | X9: 宿泊費 | AB9: 雑費
A10: 1 | C10: 齋藤 豊光 | J10: 45892 | N10: 航空機・ﾊﾞｽ | T10: 18540 | X10: 0 | AB10: 2200 | AF10: 45892
N11: 電車・車(600)㎞
N12: 宮崎～久留米
A13: 2 | C13: 髙見 翼人 | J13: 45892 | N13: 航空機・ﾊﾞｽ | T13: 15050 | X13: 0 | AB13: 2200 | AF13: 45892
N14: 電車・車(460)㎞
N15: 都城～久留米
A16: 3 | C16: 蛯原 智仁 | J16: 45892 | N16: 航空機・ﾊﾞｽ | T16: 17300 | X16: 0 | AB16: 2200 | AF16: 45892
N17: 電車・車(540)㎞
N18: 宮崎～久留米
A19: 4 | C19: 中村 里惟 | J19: 45892 | N19: 航空機・ﾊﾞｽ | T19: 16740 | X19: 0 | AB19: 2200 | AF19: 45892
N20: 電車・車(520)㎞
N21: 宮崎～久留米
A22: 5
A25: 6
A28: 7
A31: 8
A34: 9
A37: 10
P40: 合 計 | T40: =SUM(T10:W39) -> 67630 | X40: =SUM(X10:AA39) -> 0 | AB40: =SUM(AB10:AE39) -> 8800 | AF40: 旅費合計 | AL40: =SUM(T40:AE40) -> 76430
A41: 記入責任者氏名( 齋藤 豊光 ) | AB41: 電話番号(０９０－８２２４－０８４２ )
A42: 記入上の注意
A43: ① 金額欄は、同額であっても「同上」、「〃」で記入せず、必ず金額を記入のこと。
A44: ② 受領した本人が自署または押印すること。
A45: 航空機利用の場合、領収書（利用者氏名・利用区間・便名・搭乗日が記載されているもの）を添付すること。
A46: ③ 旅行業者等に交通手段・宿泊等を一括手配（依頼）し利用した場合は、旅行業者の領収書を添付する。
A47: 但し、内訳として交通費と宿泊費の明細を添付のこと。
A48: ④ 交通費は、最も経済的な通常の経路、方法により算出すること。
A49: ⑤ 自家用車を利用した場合、出発地と目的地間の最短距離(㎞ 端数切捨)に１７円を乗じた額とする。
A50: また、有料道路利用の場合は、領収書または利用証明書を添付すること。
A51: ⑥ 加盟団体等が定めた取扱等がある場合は、その取扱等により計算した額とすること。但し、本会の基準で計算した額を
A52: 上限とし、超過する場合は補助対象外とする。(注) この場合は、加盟団体等が定めた取扱等を提出すること。
A53: ⑦ 公共交通機関を利用した場合は、利用区間名(バス停、駅)を記入すること。

Sheet 様式２－６④事業別領収書１（選手強化）
A1: 様式２－６④事業別領収書１
G3: 令和 | J3: 7 | L3: 年度 | P3: 選手強化費 領収書１
A5: 団体名 | G5: 宮崎県アイスホッケー連盟
AC7: 作成者名（ 齋藤 豊光 ）
A8: No | C8: 氏 名 | J8: 期日 | N8: 交 通 | T8: 支 払 額 | AF8: 受領日 | AP8: 受領 サイン
N9: 区 間 | T9: 交通費 | X9: 宿泊費 | AB9: 雑費
A10: 1 | C10: 齋藤 豊光 | J10: 45913 | N10: 航空機・ﾊﾞｽ | T10: 20320 | X10: 0 | AB10: 2200 | AF10: 45913
N11: 電車・車(600)㎞
N12: 宮崎～久留米
A13: 2 | C13: 髙見 翼人 | J13: 45913 | N13: 航空機・ﾊﾞｽ | T13: 16730 | X13: 0 | AB13: 2200 | AF13: 45913
N14: 電車・車(460)㎞
N15: 都城～久留米
A16: 3 | C16: 宮城 将嗣 | J16: 45913 | N16: 航空機・ﾊﾞｽ | T16: 17220 | X16: 0 | AB16: 2200 | AF16: 45913
N17: 電車・車(540)㎞
N18: 宮崎～久留米
A19: 4 | C19: 中村 里惟 | J19: 45913 | N19: 航空機・ﾊﾞｽ | T19: 18430 | X19: 0 | AB19: 2200 | AF19: 45913
N20: 電車・車(520)㎞
N21: 宮崎～久留米
A22: 5 | X22: 0
A25: 6 | X25: 0
A28: 7 | X28: 0
A31: 8
A34: 9
A37: 10
P40: 合 計 | T40: =SUM(T10:W39) -> 72700 | X40: =SUM(X10:AA39) -> 0 | AB40: =SUM(AB10:AE39) -> 8800 | AF40: 旅費合計 | AL40: =SUM(T40:AE40) -> 81500
A41: 記入責任者氏名( 齋藤 豊光 ) | AB41: 電話番号(０９０－８２２４－０８４２ )
A42: 記入上の注意
A43: ① 金額欄は、同額であっても「同上」、「〃」で記入せず、必ず金額を記入のこと。
A44: ② 受領した本人が自署または押印すること。
A45: 航空機利用の場合、領収書（利用者氏名・利用区間・便名・搭乗日が記載されているもの）を添付すること。
A46: ③ 旅行業者等に交通手段・宿泊等を一括手配（依頼）し利用した場合は、旅行業者の領収書を添付する。
A47: 但し、内訳として交通費と宿泊費の明細を添付のこと。
A48: ④ 交通費は、最も経済的な通常の経路、方法により算出すること。
A49: ⑤ 自家用車を利用した場合、出発地と目的地間の最短距離(㎞ 端数切捨)に１７円を乗じた額とする。
A50: また、有料道路利用の場合は、領収書または利用証明書を添付すること。
A51: ⑥ 加盟団体等が定めた取扱等がある場合は、その取扱等により計算した額とすること。但し、本会の基準で計算した額を
A52: 上限とし、超過する場合は補助対象外とする。(注) この場合は、加盟団体等が定めた取扱等を提出すること。
A53: ⑦ 公共交通機関を利用した場合は、利用区間名(バス停、駅)を記入すること。

Sheet 様式２－６➄事業別領収書１（選手強化）
A1: 様式２－６➄事業別領収書１
G3: 令和 | J3: 7 | L3: 年度 | P3: 選手強化費 領収書１
A5: 団体名 | G5: 宮崎県アイスホッケー連盟
AC7: 作成者名（ 齋藤 豊光 ）
A8: No | C8: 氏 名 | J8: 期日 | N8: 交 通 | T8: 支 払 額 | AF8: 受領日 | AP8: 受領 サイン
N9: 区 間 | T9: 交通費 | X9: 宿泊費 | AB9: 雑費
A10: 1 | C10: 齋藤 豊光 | J10: 45927 | N10: 航空機・ﾊﾞｽ | T10: 21070 | X10: 0 | AB10: 2200 | AF10: 45927
N11: 電車・車(640)㎞
N12: 宮崎～福岡
A13: 2 | C13: 髙見 翼人 | J13: 45927 | N13: 航空機・ﾊﾞｽ | T13: 17780 | X13: 0 | AB13: 2200 | AF13: 45927
N14: 電車・車(540)㎞
N15: 都城～福岡
A16: 3 | C16: 谷脇 優二 | J16: 45927 | N16: 航空機・ﾊﾞｽ | T16: 18930 | X16: 0 | AB16: 2200 | AF16: 45927
N17: 電車・車(540)㎞
N18: 宮崎～福岡
A19: 4 | C19: 蛯原 智仁 | J19: 45927 | N19: 航空機・ﾊﾞｽ | T19: 19100 | X19: 0 | AB19: 2200 | AF19: 45927
N20: 電車・車(600)㎞
N21: 宮崎～福岡
A22: 5
A25: 6
A28: 7
A31: 8
A34: 9
A37: 10
P40: 合 計 | T40: =SUM(T10:W39) -> 76880 | X40: =SUM(X10:AA39) -> 0 | AB40: =SUM(AB10:AE39) -> 8800 | AF40: 旅費合計 | AL40: =SUM(T40:AE40) -> 85680
A41: 記入責任者氏名( 齋藤 豊光 ) | AB41: 電話番号(０９０－８２２４－０８４２ )
A42: 記入上の注意
A43: ① 金額欄は、同額であっても「同上」、「〃」で記入せず、必ず金額を記入のこと。
A44: ② 受領した本人が自署または押印すること。
A45: 航空機利用の場合、領収書（利用者氏名・利用区間・便名・搭乗日が記載されているもの）を添付すること。
A46: ③ 旅行業者等に交通手段・宿泊等を一括手配（依頼）し利用した場合は、旅行業者の領収書を添付する。
A47: 但し、内訳として交通費と宿泊費の明細を添付のこと。
A48: ④ 交通費は、最も経済的な通常の経路、方法により算出すること。
A49: ⑤ 自家用車を利用した場合、出発地と目的地間の最短距離(㎞ 端数切捨)に１７円を乗じた額とする。
A50: また、有料道路利用の場合は、領収書または利用証明書を添付すること。
A51: ⑥ 加盟団体等が定めた取扱等がある場合は、その取扱等により計算した額とすること。但し、本会の基準で計算した額を
A52: 上限とし、超過する場合は補助対象外とする。(注) この場合は、加盟団体等が定めた取扱等を提出すること。
A53: ⑦ 公共交通機関を利用した場合は、利用区間名(バス停、駅)を記入すること。

Sheet 様式２－６⑥事業別領収書１（選手強化）
A1: 様式２－６⑥事業別領収書１
G3: 令和 | J3: 7 | L3: 年度 | P3: 選手強化費 領収書１
A5: 団体名 | G5: 宮崎県アイスホッケー連盟
AC7: 作成者名（ 齋藤 豊光 ）
A8: No | C8: 氏 名 | J8: 期日 | N8: 交 通 | T8: 支 払 額 | AF8: 受領日 | AP8: 受領 サイン
N9: 区 間 | T9: 交通費 | X9: 宿泊費 | AB9: 雑費
A10: 1 | C10: 齋藤 豊光 | J10: 45934 | N10: 航空機・ﾊﾞｽ | T10: 18540 | X10: 0 | AB10: 2200 | AF10: 45934
N11: 電車・車(600)㎞
N12: 宮崎～久留米
A13: 2 | C13: 髙見 翼人 | J13: 45934 | N13: 航空機・ﾊﾞｽ | T13: 15160 | X13: 0 | AB13: 2200 | AF13: 45934
N14: 電車・車(460)㎞
N15: 都城～久留米
A16: 3 | X16: 0
A19: 4 | X19: 0
A22: 5 | X22: 0
A25: 6 | X25: 0
A28: 7 | X28: 0
A31: 8
A34: 9
A37: 10
P40: 合 計 | T40: =SUM(T10:W39) -> 33700 | X40: =SUM(X10:AA39) -> 0 | AB40: =SUM(AB10:AE39) -> 4400 | AF40: 旅費合計 | AL40: =SUM(T40:AE40) -> 38100
A41: 記入責任者氏名( 齋藤 豊光 ) | AB41: 電話番号(０９０－８２２４－０８４２ )
A42: 記入上の注意
A43: ① 金額欄は、同額であっても「同上」、「〃」で記入せず、必ず金額を記入のこと。
A44: ② 受領した本人が自署または押印すること。
A45: 航空機利用の場合、領収書（利用者氏名・利用区間・便名・搭乗日が記載されているもの）を添付すること。
A46: ③ 旅行業者等に交通手段・宿泊等を一括手配（依頼）し利用した場合は、旅行業者の領収書を添付する。
A47: 但し、内訳として交通費と宿泊費の明細を添付のこと。
A48: ④ 交通費は、最も経済的な通常の経路、方法により算出すること。
A49: ⑤ 自家用車を利用した場合、出発地と目的地間の最短距離(㎞ 端数切捨)に１７円を乗じた額とする。
A50: また、有料道路利用の場合は、領収書または利用証明書を添付すること。
A51: ⑥ 加盟団体等が定めた取扱等がある場合は、その取扱等により計算した額とすること。但し、本会の基準で計算した額を
A52: 上限とし、超過する場合は補助対象外とする。(注) この場合は、加盟団体等が定めた取扱等を提出すること。
A53: ⑦ 公共交通機関を利用した場合は、利用区間名(バス停、駅)を記入すること。

Sheet 様式２－６⑦事業別領収書１（選手強化）
A1: 様式２－６⑦事業別領収書１
G3: 令和 | J3: 7 | L3: 年度 | P3: 選手強化費 領収書１
A5: 団体名 | G5: 宮崎県アイスホッケー連盟
AC7: 作成者名（ 齋藤 豊光 ）
A8: No | C8: 氏 名 | J8: 期日 | N8: 交 通 | T8: 支 払 額 | AF8: 受領日 | AP8: 受領 サイン
N9: 区 間 | T9: 交通費 | X9: 宿泊費 | AB9: 雑費
A10: 1 | C10: 齋藤 豊光 | J10: 45955 | N10: 航空機・ﾊﾞｽ | T10: 18540 | X10: 0 | AB10: 2200 | AF10: 45955
N11: 電車・車(600)㎞
N12: 宮崎～久留米
A13: 2 | C13: 髙見 翼人 | J13: 45955 | N13: 航空機・ﾊﾞｽ | T13: 15160 | X13: 0 | AB13: 2200 | AF13: 45955
N14: 電車・車(460)㎞
N15: 都城～久留米
A16: 3 | C16: 蛯原 智仁 | J16: 45955 | N16: 航空機・ﾊﾞｽ | T16: 17300 | X16: 0 | AB16: 2200 | AF16: 45955
N17: 電車・車(540)㎞
N18: 宮崎～久留米
A19: 4
A22: 5
A25: 6
A28: 7
A31: 8
A34: 9
A37: 10
P40: 合 計 | T40: =SUM(T10:W39) -> 51000 | X40: =SUM(X10:AA39) -> 0 | AB40: =SUM(AB10:AE39) -> 6600 | AF40: 旅費合計 | AL40: =SUM(T40:AE40) -> 57600
A41: 記入責任者氏名( 齋藤 豊光 ) | AB41: 電話番号(０９０－８２２４－０８４２ )
A42: 記入上の注意
A43: ① 金額欄は、同額であっても「同上」、「〃」で記入せず、必ず金額を記入のこと。
A44: ② 受領した本人が自署または押印すること。
A45: 航空機利用の場合、領収書（利用者氏名・利用区間・便名・搭乗日が記載されているもの）を添付すること。
A46: ③ 旅行業者等に交通手段・宿泊等を一括手配（依頼）し利用した場合は、旅行業者の領収書を添付する。
A47: 但し、内訳として交通費と宿泊費の明細を添付のこと。
A48: ④ 交通費は、最も経済的な通常の経路、方法により算出すること。
A49: ⑤ 自家用車を利用した場合、出発地と目的地間の最短距離(㎞ 端数切捨)に１７円を乗じた額とする。
A50: また、有料道路利用の場合は、領収書または利用証明書を添付すること。
A51: ⑥ 加盟団体等が定めた取扱等がある場合は、その取扱等により計算した額とすること。但し、本会の基準で計算した額を
A52: 上限とし、超過する場合は補助対象外とする。(注) この場合は、加盟団体等が定めた取扱等を提出すること。
A53: ⑦ 公共交通機関を利用した場合は、利用区間名(バス停、駅)を記入すること。

Sheet 様式２－６⑧事業別領収書１（選手強化）
A1: 様式２－６⑧事業別領収書１
G3: 令和 | J3: 7 | L3: 年度 | P3: 選手強化費 領収書１
A5: 団体名 | G5: 宮崎県アイスホッケー連盟
AC7: 作成者名（ 齋藤 豊光 ）
A8: No | C8: 氏 名 | J8: 期日 | N8: 交 通 | T8: 支 払 額 | AF8: 受領日 | AP8: 受領 サイン
N9: 区 間 | T9: 交通費 | X9: 宿泊費 | AB9: 雑費
A10: 1 | C10: 齋藤 豊光 | J10: 45969 | N10: 航空機・ﾊﾞｽ | T10: 19730 | X10: 0 | AB10: 2200 | AF10: 45969
N11: 電車・車(600)㎞
N12: 宮崎～福岡
A13: 2 | C13: 髙見 翼人 | J13: 45969 | N13: 航空機・ﾊﾞｽ | T13: 9180 | X13: 0 | AB13: 2200 | AF13: 45969
N14: 電車・車(540)㎞
N15: 都城～福岡
A16: 3 | C16: 蛯原 智仁 | J16: 45969 | N16: 航空機・ﾊﾞｽ | T16: 19100 | X16: 0 | AB16: 2200 | AF16: 45969
N17: 電車・車(600)㎞
N18: 宮崎～福岡
A19: 4 | C19: 中村 里惟 | J19: 45969 | N19: 航空機・ﾊﾞｽ | T19: 19950 | X19: 0 | AB19: 2200 | AF19: 45969
N20: 電車・車(600)㎞
N21: 宮崎～福岡
A22: 5
A25: 6
A28: 7
A31: 8
A34: 9
A37: 10
P40: 合 計 | T40: =SUM(T10:W39) -> 67960 | X40: =SUM(X10:AA39) -> 0 | AB40: =SUM(AB10:AE39) -> 8800 | AF40: 旅費合計 | AL40: =SUM(T40:AE40) -> 76760
A41: 記入責任者氏名( 齋藤 豊光 ) | AB41: 電話番号(０９０－８２２４－０８４２ )
A42: 記入上の注意
A43: ① 金額欄は、同額であっても「同上」、「〃」で記入せず、必ず金額を記入のこと。
A44: ② 受領した本人が自署または押印すること。
A45: 航空機利用の場合、領収書（利用者氏名・利用区間・便名・搭乗日が記載されているもの）を添付すること。
A46: ③ 旅行業者等に交通手段・宿泊等を一括手配（依頼）し利用した場合は、旅行業者の領収書を添付する。
A47: 但し、内訳として交通費と宿泊費の明細を添付のこと。
A48: ④ 交通費は、最も経済的な通常の経路、方法により算出すること。
A49: ⑤ 自家用車を利用した場合、出発地と目的地間の最短距離(㎞ 端数切捨)に１７円を乗じた額とする。
A50: また、有料道路利用の場合は、領収書または利用証明書を添付すること。
A51: ⑥ 加盟団体等が定めた取扱等がある場合は、その取扱等により計算した額とすること。但し、本会の基準で計算した額を
A52: 上限とし、超過する場合は補助対象外とする。(注) この場合は、加盟団体等が定めた取扱等を提出すること。
A53: ⑦ 公共交通機関を利用した場合は、利用区間名(バス停、駅)を記入すること。

Sheet 様式２－６⑨事業別領収書１（選手強化）
A1: 様式２－６⑨事業別領収書１
G3: 令和 | J3: 7 | L3: 年度 | P3: 選手強化費 領収書１
A5: 団体名 | G5: 宮崎県アイスホッケー連盟
AC7: 作成者名（ 齋藤 豊光 ）
A8: No | C8: 氏 名 | J8: 期日 | N8: 交 通 | T8: 支 払 額 | AF8: 受領日 | AP8: 受領 サイン
N9: 区 間 | T9: 交通費 | X9: 宿泊費 | AB9: 雑費
A10: 1 | C10: 齋藤 豊光 | J10: 45983 | N10: 航空機・ﾊﾞｽ | T10: 20320 | X10: 0 | AB10: 2200 | AF10: 45983
N11: 電車・車(600)㎞
N12: 宮崎～久留米
A13: 2 | C13: 髙見 翼人 | J13: 45983 | N13: 航空機・ﾊﾞｽ | T13: 16730 | X13: 0 | AB13: 2200 | AF13: 45983
N14: 電車・車(460)㎞
N15: 都城～久留米
A16: 3 | C16: 蛯原 智仁 | J16: 45983 | N16: 航空機・ﾊﾞｽ | T16: 19160 | X16: 0 | AB16: 2200 | AF16: 45983
N17: 電車・車(540)㎞
N18: 宮崎～久留米
A19: 4 | C19: 中村 里惟 | J19: 45983 | N19: 航空機・ﾊﾞｽ | T19: 18430 | X19: 0 | AB19: 2200 | AF19: 45983
N20: 電車・車(520)㎞
N21: 宮崎～久留米
A22: 5
A25: 6
A28: 7
A31: 8
A34: 9
A37: 10
P40: 合 計 | T40: =SUM(T10:W39) -> 74640 | X40: =SUM(X10:AA39) -> 0 | AB40: =SUM(AB10:AE39) -> 8800 | AF40: 旅費合計 | AL40: =SUM(T40:AE40) -> 83440
A41: 記入責任者氏名( 齋藤 豊光 ) | AB41: 電話番号(０９０－８２２４－０８４２ )
A42: 記入上の注意
A43: ① 金額欄は、同額であっても「同上」、「〃」で記入せず、必ず金額を記入のこと。
A44: ② 受領した本人が自署または押印すること。
A45: 航空機利用の場合、領収書（利用者氏名・利用区間・便名・搭乗日が記載されているもの）を添付すること。
A46: ③ 旅行業者等に交通手段・宿泊等を一括手配（依頼）し利用した場合は、旅行業者の領収書を添付する。
A47: 但し、内訳として交通費と宿泊費の明細を添付のこと。
A48: ④ 交通費は、最も経済的な通常の経路、方法により算出すること。
A49: ⑤ 自家用車を利用した場合、出発地と目的地間の最短距離(㎞ 端数切捨)に１７円を乗じた額とする。
A50: また、有料道路利用の場合は、領収書または利用証明書を添付すること。
A51: ⑥ 加盟団体等が定めた取扱等がある場合は、その取扱等により計算した額とすること。但し、本会の基準で計算した額を
A52: 上限とし、超過する場合は補助対象外とする。(注) この場合は、加盟団体等が定めた取扱等を提出すること。
A53: ⑦ 公共交通機関を利用した場合は、利用区間名(バス停、駅)を記入すること。

Sheet 様式２－６⑩事業別領収書１（選手強化）
A1: 様式２－６⑩事業別領収書１
G3: 令和 | J3: 7 | L3: 年度 | P3: 選手強化費 領収書１
A5: 団体名 | G5: 宮崎県アイスホッケー連盟
AC7: 作成者名（ 齋藤 豊光 ）
A8: No | C8: 氏 名 | J8: 期日 | N8: 交 通 | T8: 支 払 額 | AF8: 受領日 | AP8: 受領 サイン
N9: 区 間 | T9: 交通費 | X9: 宿泊費 | AB9: 雑費
A10: 1 | C10: 中村 里惟 | J10: 46018 | N10: 航空機・ﾊﾞｽ | T10: 20120 | X10: 0 | AB10: 2200 | AF10: 46018
N11: 電車・車(520)㎞
N12: 宮崎～久留米
A13: 2
A16: 3
A19: 4
A22: 5
A25: 6
A28: 7
A31: 8
A34: 9
A37: 10
P40: 合 計 | T40: =SUM(T10:W39) -> 20120 | X40: =SUM(X10:AA39) -> 0 | AB40: =SUM(AB10:AE39) -> 2200 | AF40: 旅費合計 | AL40: =SUM(T40:AE40) -> 22320
A41: 記入責任者氏名( 齋藤 豊光 ) | AB41: 電話番号(０９０－８２２４－０８４２ )
A42: 記入上の注意
A43: ① 金額欄は、同額であっても「同上」、「〃」で記入せず、必ず金額を記入のこと。
A44: ② 受領した本人が自署または押印すること。
A45: 航空機利用の場合、領収書（利用者氏名・利用区間・便名・搭乗日が記載されているもの）を添付すること。
A46: ③ 旅行業者等に交通手段・宿泊等を一括手配（依頼）し利用した場合は、旅行業者の領収書を添付する。
A47: 但し、内訳として交通費と宿泊費の明細を添付のこと。
A48: ④ 交通費は、最も経済的な通常の経路、方法により算出すること。
A49: ⑤ 自家用車を利用した場合、出発地と目的地間の最短距離(㎞ 端数切捨)に１７円を乗じた額とする。
A50: また、有料道路利用の場合は、領収書または利用証明書を添付すること。
A51: ⑥ 加盟団体等が定めた取扱等がある場合は、その取扱等により計算した額とすること。但し、本会の基準で計算した額を
A52: 上限とし、超過する場合は補助対象外とする。(注) この場合は、加盟団体等が定めた取扱等を提出すること。
A53: ⑦ 公共交通機関を利用した場合は、利用区間名(バス停、駅)を記入すること。

Sheet 様式２－６⑪事業別領収書１（選手強化）
A1: 様式２－６⑪事業別領収書１
G3: 令和 | J3: 7 | L3: 年度 | P3: 選手強化費 領収書１
A5: 団体名 | G5: 宮崎県アイスホッケー連盟
AC7: 作成者名（ 齋藤 豊光 ）
A8: No | C8: 氏 名 | J8: 期日 | N8: 交 通 | T8: 支 払 額 | AF8: 受領日 | AP8: 受領 サイン
N9: 区 間 | T9: 交通費 | X9: 宿泊費 | AB9: 雑費
A10: 1 | C10: 蛯原 智仁 | J10: 46032 | N10: 航空機・ﾊﾞｽ | T10: 4310 | X10: 0 | AB10: 200 | AF10: 46032
N11: 電車・車( ０ )㎞
N12: 宮崎～えびの
A13: 2 | X13: 0
A16: 3 | X16: 0
A19: 4 | X19: 0
A22: 5 | X22: 0
A25: 6 | X25: 0
A28: 7 | X28: 0
A31: 8
A34: 9
A37: 10
P40: 合 計 | T40: =SUM(T10:W39) -> 4310 | X40: =SUM(X10:AA39) -> 0 | AB40: =SUM(AB10:AE39) -> 200 | AF40: 旅費合計 | AL40: =SUM(T40:AE40) -> 4510
A41: 記入責任者氏名( 齋藤 豊光 ) | AB41: 電話番号(０９０－８２２４－０８４２ )
A42: 記入上の注意
A43: ① 金額欄は、同額であっても「同上」、「〃」で記入せず、必ず金額を記入のこと。
A44: ② 受領した本人が自署または押印すること。
A45: 航空機利用の場合、領収書（利用者氏名・利用区間・便名・搭乗日が記載されているもの）を添付すること。
A46: ③ 旅行業者等に交通手段・宿泊等を一括手配（依頼）し利用した場合は、旅行業者の領収書を添付する。
A47: 但し、内訳として交通費と宿泊費の明細を添付のこと。
A48: ④ 交通費は、最も経済的な通常の経路、方法により算出すること。
A49: ⑤ 自家用車を利用した場合、出発地と目的地間の最短距離(㎞ 端数切捨)に１７円を乗じた額とする。
A50: また、有料道路利用の場合は、領収書または利用証明書を添付すること。
A51: ⑥ 加盟団体等が定めた取扱等がある場合は、その取扱等により計算した額とすること。但し、本会の基準で計算した額を
A52: 上限とし、超過する場合は補助対象外とする。(注) この場合は、加盟団体等が定めた取扱等を提出すること。
A53: ⑦ 公共交通機関を利用した場合は、利用区間名(バス停、駅)を記入すること。

Sheet 様式２－６⑫事業別領収書１（選手強化）
A1: 様式２－６⑫事業別領収書１
G3: 令和 | J3: 7 | L3: 年度 | P3: 選手強化費 領収書１
A5: 団体名 | G5: 宮崎県アイスホッケー連盟
AC7: 作成者名（ 齋藤 豊光 ）
A8: No | C8: 氏 名 | J8: 期日 | N8: 交 通 | T8: 支 払 額 | AF8: 受領日 | AP8: 受領 サイン
N9: 区 間 | T9: 交通費 | X9: 宿泊費 | AB9: 雑費
A10: 1 | C10: 中村 里惟 | J10: 46039 | N10: 航空機・ﾊﾞｽ | T10: 17170 | X10: 0 | AB10: 2200 | AF10: 46039
N11: 電車・車(520)㎞
N12: 宮崎～久留米
A13: 2 | X13: 0
A16: 3 | X16: 0
A19: 4 | X19: 0
A22: 5 | X22: 0
A25: 6 | X25: 0
A28: 7 | X28: 0
A31: 8
A34: 9
A37: 10
P40: 合 計 | T40: =SUM(T10:W39) -> 17170 | X40: =SUM(X10:AA39) -> 0 | AB40: =SUM(AB10:AE39) -> 2200 | AF40: 旅費合計 | AL40: =SUM(T40:AE40) -> 19370
A41: 記入責任者氏名( 齋藤 豊光 ) | AB41: 電話番号(０９０－８２２４－０８４２ )
A42: 記入上の注意
A43: ① 金額欄は、同額であっても「同上」、「〃」で記入せず、必ず金額を記入のこと。
A44: ② 受領した本人が自署または押印すること。
A45: 航空機利用の場合、領収書（利用者氏名・利用区間・便名・搭乗日が記載されているもの）を添付すること。
A46: ③ 旅行業者等に交通手段・宿泊等を一括手配（依頼）し利用した場合は、旅行業者の領収書を添付する。
A47: 但し、内訳として交通費と宿泊費の明細を添付のこと。
A48: ④ 交通費は、最も経済的な通常の経路、方法により算出すること。
A49: ⑤ 自家用車を利用した場合、出発地と目的地間の最短距離(㎞ 端数切捨)に１７円を乗じた額とする。
A50: また、有料道路利用の場合は、領収書または利用証明書を添付すること。
A51: ⑥ 加盟団体等が定めた取扱等がある場合は、その取扱等により計算した額とすること。但し、本会の基準で計算した額を
A52: 上限とし、超過する場合は補助対象外とする。(注) この場合は、加盟団体等が定めた取扱等を提出すること。
A53: ⑦ 公共交通機関を利用した場合は、利用区間名(バス停、駅)を記入すること。

Sheet 様式２－６⑬事業別領収書１（選手強化）
A1: 様式２－６⑬事業別領収書１
G3: 令和 | J3: 7 | L3: 年度 | P3: 選手強化費 領収書１
A5: 団体名 | G5: 宮崎県アイスホッケー連盟
AC7: 作成者名（ 齋藤 豊光 ）
A8: No | C8: 氏 名 | J8: 期日 | N8: 交 通 | T8: 支 払 額 | AF8: 受領日 | AP8: 受領 サイン
N9: 区 間 | T9: 交通費 | X9: 宿泊費 | AB9: 雑費
A10: 1 | C10: 蛯原 智仁 | J10: 1/24～ 25 | N10: 航空機・ﾊﾞｽ | T10: 19100 | X10: 6250 | AB10: 2200 | AF10: 46047
N11: 電車・車(600)㎞
N12: 宮崎～福岡
A13: 2 | C13: 中村 里惟 | J13: 1/24～ 25 | N13: 航空機・ﾊﾞｽ | T13: 19390 | X13: 6250 | AB13: 2200 | AF13: 46047
N14: 電車・車(600)㎞
N15: 宮崎～福岡
A16: 3 | C16: 山田 幸治 | J16: 1/24～ 25 | N16: 航空機・ﾊﾞｽ | T16: 19730 | X16: 6250 | AB16: 2200 | AF16: 46047
N17: 電車・車(600)㎞
N18: 宮崎～福岡
A19: 4 | C19: 髙見 翼人 | J19: 1/24～ 25 | N19: 航空機・ﾊﾞｽ | T19: 17810 | X19: 6250 | AB19: 2200 | AF19: 46047
N20: 電車・車(540)㎞
N21: 都城～福岡
A22: 5 | C22: 松本 紘煕 | J22: 1/24～ 25 | N22: 航空機・ﾊﾞｽ | T22: 19780 | X22: 6250 | AB22: 2200 | AF22: 46047
N23: 電車・車(600)㎞
N24: 宮崎～福岡
A25: 6 | C25: 日髙 雅壮 | J25: 1/24～ 25 | N25: 航空機・ﾊﾞｽ | X25: 6250 | AB25: 2200 | AF25: 46047
N26: 電車・車(0)㎞
N27: 宮崎～福岡
A28: 7 | C28: 小林 大祐 | J28: 1/24～ 25 | N28: 航空機・ﾊﾞｽ | X28: 6250 | AB28: 2200 | AF28: 46047
N29: 電車・車(0)㎞
N30: 宮崎～福岡
A31: 8 | C31: 新森 康弘 | J31: 1/24～ 25 | N31: 航空機・ﾊﾞｽ | X31: 6250 | AB31: 2200 | AF31: 46047
N32: 電車・車(0)㎞
N33: 宮崎～福岡
A34: 9 | C34: 児玉 恵吾 | J34: 1/24～ 25 | N34: 航空機・ﾊﾞｽ | X34: 6250 | AB34: 2200 | AF34: 46047
N35: 電車・車(0)㎞
N36: 宮崎～福岡
A37: 10 | C37: 宮城 将嗣 | J37: 1/24～ 25 | N37: 航空機・ﾊﾞｽ | X37: 6250 | AB37: 2200 | AF37: 46047
N38: 電車・車(0)㎞
N39: 宮崎～福岡
P40: 合 計 | T40: =SUM(T10:W39) -> 95810 | X40: =SUM(X10:AA39) -> 62500 | AB40: =SUM(AB10:AE39) -> 22000 | AF40: 旅費合計 | AL40: =SUM(T40:AE40) -> 180310
A41: 記入責任者氏名( 齋藤 豊光 ) | AB41: 電話番号(０９０－８２２４－０８４２ )
A42: 記入上の注意
A43: ① 金額欄は、同額であっても「同上」、「〃」で記入せず、必ず金額を記入のこと。
...

Sheet 様式２－６⑭事業別領収書１（選手強化）
A1: 様式２－６⑭事業別領収書１
G3: 令和 | J3: 7 | L3: 年度 | P3: 選手強化費 領収書１
A5: 団体名 | G5: 宮崎県アイスホッケー連盟
AC7: 作成者名（ 齋藤 豊光 ）
A8: No | C8: 氏 名 | J8: 期日 | N8: 交 通 | T8: 支 払 額 | AF8: 受領日 | AP8: 受領 サイン
N9: 区 間 | T9: 交通費 | X9: 宿泊費 | AB9: 雑費
A10: 1 | C10: 蛯原 智仁 | J10: 46052 | N10: 航空機・ﾊﾞｽ | T10: 20860 | X10: 0 | AB10: 2200 | AF10: 46052
N11: 電車・車(600)㎞
N12: 宮崎～福岡
A13: 2 | X13: 0
A16: 3 | X16: 0
A19: 4 | X19: 0
A22: 5 | X22: 0
A25: 6 | X25: 0
A28: 7 | X28: 0
A31: 8
A34: 9
A37: 10
P40: 合 計 | T40: =SUM(T10:W39) -> 20860 | X40: =SUM(X10:AA39) -> 0 | AB40: =SUM(AB10:AE39) -> 2200 | AF40: 旅費合計 | AL40: =SUM(T40:AE40) -> 23060
A41: 記入責任者氏名( 齋藤 豊光 ) | AB41: 電話番号(０９０－８２２４－０８４２ )
A42: 記入上の注意
A43: ① 金額欄は、同額であっても「同上」、「〃」で記入せず、必ず金額を記入のこと。
A44: ② 受領した本人が自署または押印すること。
A45: 航空機利用の場合、領収書（利用者氏名・利用区間・便名・搭乗日が記載されているもの）を添付すること。
A46: ③ 旅行業者等に交通手段・宿泊等を一括手配（依頼）し利用した場合は、旅行業者の領収書を添付する。
A47: 但し、内訳として交通費と宿泊費の明細を添付のこと。
A48: ④ 交通費は、最も経済的な通常の経路、方法により算出すること。
A49: ⑤ 自家用車を利用した場合、出発地と目的地間の最短距離(㎞ 端数切捨)に１７円を乗じた額とする。
A50: また、有料道路利用の場合は、領収書または利用証明書を添付すること。
A51: ⑥ 加盟団体等が定めた取扱等がある場合は、その取扱等により計算した額とすること。但し、本会の基準で計算した額を
A52: 上限とし、超過する場合は補助対象外とする。(注) この場合は、加盟団体等が定めた取扱等を提出すること。
A53: ⑦ 公共交通機関を利用した場合は、利用区間名(バス停、駅)を記入すること。

Sheet 様式２－６⑮事業別領収書１（選手強化）
A1: 様式２－６⑮事業別領収書１
G3: 令和 | J3: 7 | L3: 年度 | P3: 選手強化費 領収書１
A5: 団体名 | G5: 宮崎県アイスホッケー連盟
AC7: 作成者名（ 齋藤 豊光 ）
A8: No | C8: 氏 名 | J8: 期日 | N8: 交 通 | T8: 支 払 額 | AF8: 受領日 | AP8: 受領 サイン
N9: 区 間 | T9: 交通費 | X9: 宿泊費 | AB9: 雑費
A10: 1 | C10: 宮城 将嗣 | J10: 46060 | N10: 航空機・ﾊﾞｽ | T10: 11040 | X10: 0 | AB10: 2200 | AF10: 46060
N11: 電車・車(370)㎞
N12: 清武～熊本
A13: 2 | C13: 山田 幸司 | J13: 46060 | N13: 航空機・ﾊﾞｽ | T13: 12320 | X13: 0 | AB13: 2200 | AF13: 46060
N14: 電車・車(380)㎞
N15: 宮崎～熊本
A16: 3
A19: 4
A22: 5
A25: 6
A28: 7
A31: 8
A34: 9
A37: 10
P40: 合 計 | T40: =SUM(T10:W39) -> 23360 | X40: =SUM(X10:AA39) -> 0 | AB40: =SUM(AB10:AE39) -> 4400 | AF40: 旅費合計 | AL40: =SUM(T40:AE40) -> 27760
A41: 記入責任者氏名( 齋藤 豊光 ) | AB41: 電話番号(０９０－８２２４－０８４２ )
A42: 記入上の注意
A43: ① 金額欄は、同額であっても「同上」、「〃」で記入せず、必ず金額を記入のこと。
A44: ② 受領した本人が自署または押印すること。
A45: 航空機利用の場合、領収書（利用者氏名・利用区間・便名・搭乗日が記載されているもの）を添付すること。
A46: ③ 旅行業者等に交通手段・宿泊等を一括手配（依頼）し利用した場合は、旅行業者の領収書を添付する。
A47: 但し、内訳として交通費と宿泊費の明細を添付のこと。
A48: ④ 交通費は、最も経済的な通常の経路、方法により算出すること。
A49: ⑤ 自家用車を利用した場合、出発地と目的地間の最短距離(㎞ 端数切捨)に１７円を乗じた額とする。
A50: また、有料道路利用の場合は、領収書または利用証明書を添付すること。
A51: ⑥ 加盟団体等が定めた取扱等がある場合は、その取扱等により計算した額とすること。但し、本会の基準で計算した額を
A52: 上限とし、超過する場合は補助対象外とする。(注) この場合は、加盟団体等が定めた取扱等を提出すること。
A53: ⑦ 公共交通機関を利用した場合は、利用区間名(バス停、駅)を記入すること。

Sheet 様式２－６⑯事業別領収書１（選手強化）
A1: 様式２－６⑯事業別領収書１
G3: 令和 | J3: 7 | L3: 年度 | P3: 選手強化費 領収書１
A5: 団体名 | G5: 宮崎県アイスホッケー連盟
AC7: 作成者名（ 齋藤 豊光 ）
A8: No | C8: 氏 名 | J8: 期日 | N8: 交 通 | T8: 支 払 額 | AF8: 受領日 | AP8: 受領 サイン
N9: 区 間 | T9: 交通費 | X9: 宿泊費 | AB9: 雑費
A10: 1 | C10: 蛯原 智仁 | J10: 46074 | N10: 航空機・ﾊﾞｽ | T10: 13250 | X10: 0 | AB10: 2200 | AF10: 46074
N11: 電車・車(370)㎞
N12: 清武～熊本
A13: 2 | C13: 山田 幸司 | J13: 46074 | N13: 航空機・ﾊﾞｽ | T13: 13460 | X13: 0 | AB13: 2200 | AF13: 46074
N14: 電車・車(380)㎞
N15: 宮崎～熊本
A16: 3
A19: 4
A22: 5
A25: 6
A28: 7
A31: 8
A34: 9
A37: 10
P40: 合 計 | T40: =SUM(T10:W39) -> 26710 | X40: =SUM(X10:AA39) -> 0 | AB40: =SUM(AB10:AE39) -> 4400 | AF40: 旅費合計 | AL40: =SUM(T40:AE40) -> 31110
A41: 記入責任者氏名( 齋藤 豊光 ) | AB41: 電話番号(０９０－８２２４－０８４２ )
A42: 記入上の注意
A43: ① 金額欄は、同額であっても「同上」、「〃」で記入せず、必ず金額を記入のこと。
A44: ② 受領した本人が自署または押印すること。
A45: 航空機利用の場合、領収書（利用者氏名・利用区間・便名・搭乗日が記載されているもの）を添付すること。
A46: ③ 旅行業者等に交通手段・宿泊等を一括手配（依頼）し利用した場合は、旅行業者の領収書を添付する。
A47: 但し、内訳として交通費と宿泊費の明細を添付のこと。
A48: ④ 交通費は、最も経済的な通常の経路、方法により算出すること。
A49: ⑤ 自家用車を利用した場合、出発地と目的地間の最短距離(㎞ 端数切捨)に１７円を乗じた額とする。
A50: また、有料道路利用の場合は、領収書または利用証明書を添付すること。
A51: ⑥ 加盟団体等が定めた取扱等がある場合は、その取扱等により計算した額とすること。但し、本会の基準で計算した額を
A52: 上限とし、超過する場合は補助対象外とする。(注) この場合は、加盟団体等が定めた取扱等を提出すること。
A53: ⑦ 公共交通機関を利用した場合は、利用区間名(バス停、駅)を記入すること。

Sheet 様式２－６⑰事業別領収書１（選手強化）
A1: 様式２－６⑰事業別領収書１
G3: 令和 | J3: 7 | L3: 年度 | P3: 選手強化費 領収書１
A5: 団体名 | G5: 宮崎県アイスホッケー連盟
AC7: 作成者名（ 齋藤 豊光 ）
A8: No | C8: 氏 名 | J8: 期日 | N8: 交 通 | T8: 支 払 額 | AF8: 受領日 | AP8: 受領 サイン
N9: 区 間 | T9: 交通費 | X9: 宿泊費 | AB9: 雑費
A10: 1 | C10: 山田 幸司 | J10: 2/28～ 3/1 | N10: 航空機・ﾊﾞｽ | T10: 19730 | X10: 6250 | AB10: 2200 | AF10: 46082
N11: 電車・車(600)㎞
N12: 宮崎～福岡
A13: 2 | C13: 松本 紘煕 | J13: 2/28～ 3/1 | N13: 航空機・ﾊﾞｽ | T13: 19730 | X13: 6250 | AB13: 2200 | AF13: 46082
N14: 電車・車(600)㎞
N15: 宮崎～福岡
A16: 3 | C16: 宮城 将嗣 | J16: 2/28～ 3/1 | N16: 航空機・ﾊﾞｽ | T16: 0 | X16: 6250 | AB16: 2200 | AF16: 46082
N17: 電車・車(0)㎞
N18: 宮崎～福岡
A19: 4
A22: 5
A25: 6
A28: 7
A31: 8
A34: 9
A37: 10
P40: 合 計 | T40: =SUM(T10:W39) -> 39460 | X40: =SUM(X10:AA39) -> 18750 | AB40: =SUM(AB10:AE39) -> 6600 | AF40: 旅費合計 | AL40: =SUM(T40:AE40) -> 64810
A41: 記入責任者氏名( 齋藤 豊光 ) | AB41: 電話番号(０９０－８２２４－０８４２ )
A42: 記入上の注意
A43: ① 金額欄は、同額であっても「同上」、「〃」で記入せず、必ず金額を記入のこと。
A44: ② 受領した本人が自署または押印すること。
A45: 航空機利用の場合、領収書（利用者氏名・利用区間・便名・搭乗日が記載されているもの）を添付すること。
A46: ③ 旅行業者等に交通手段・宿泊等を一括手配（依頼）し利用した場合は、旅行業者の領収書を添付する。
A47: 但し、内訳として交通費と宿泊費の明細を添付のこと。
A48: ④ 交通費は、最も経済的な通常の経路、方法により算出すること。
A49: ⑤ 自家用車を利用した場合、出発地と目的地間の最短距離(㎞ 端数切捨)に１７円を乗じた額とする。
A50: また、有料道路利用の場合は、領収書または利用証明書を添付すること。
A51: ⑥ 加盟団体等が定めた取扱等がある場合は、その取扱等により計算した額とすること。但し、本会の基準で計算した額を
A52: 上限とし、超過する場合は補助対象外とする。(注) この場合は、加盟団体等が定めた取扱等を提出すること。
A53: ⑦ 公共交通機関を利用した場合は、利用区間名(バス停、駅)を記入すること。

Sheet 様式２－４　事業実施・実績報告書（トップチーム）
A1: 様式２－４事業実施・実績報告書
B4: 令和 | D4: 年度 | E4: トップチーム活用事業実施状況（実績報告）
F7: 団体名
I9: 令和 年 月 日
A10: ねらい
A11: 期 日 | C11: 令和 年 月 日（ ）～ 月 日（ ）
A12: 会 場
A13: 招待チーム
A14: 本県チーム
A15: 参加人数計 | C15: 招待チーム 名 本県チーム 名
